Workbook

Sheet 手机&平板保底版销售计划数量VS 实际出货
A1: 客户 | B1: 项目名 | C1: 市场型号 | D1: 订单 类型 | E1: 产品 类型 | F1: 剩余订单 (校验公式)
G2: 1月分解 | H2: 1月实际 | I2: 2月分解 | J2: 2月实际 | K2: 3月分解 | L2: 3月实际 | M2: 4月分解 | N2: 4月实际 | O2: 5月分解 | P2: 5月实际 | Q2: 6月分解 | R2: 6月实际 | S2: 7月分解 | T2: 7月实际 | U2: 8月分解 | V2: 8月实际 | W2: 9月分解 | X2: 9月实际 | Y2: 10月分解 | Z2: 10月实际 | AA2: 11月分解 | AB2: 11月实际 | AC2: 12月分解 | AD2: 12月实际 | AE2: 全年分解 | AF2: 全年实际
G3: 小计 | H3: 小计 | I3: 小计 | J3: 小计 | K3: 小计 | L3: 小计 | M3: 小计 | N3: 小计 | O3: 小计 | P3: 小计 | Q3: 小计 | R3: 小计 | S3: 小计 | T3: 小计 | U3: 小计 | V3: 小计 | W3: 小计 | X3: 小计 | Y3: 小计 | Z3: 小计 | AA3: 小计 | AB3: 小计 | AC3: 小计 | AD3: 小计 | AE3: 总计 | AF3: 总计
G4: 数量 | H4: 数量 | I4: 数量 | J4: 数量 | K4: 数量 | L4: 数量 | M4: 数量 | N4: 数量 | O4: 数量 | P4: 数量 | Q4: 数量 | R4: 数量 | S4: 数量 | T4: 数量 | U4: 数量 | V4: 数量 | W4: 数量 | X4: 数量 | Y4: 数量 | Z4: 数量 | AA4: 数量 | AB4: 数量 | AC4: 数量 | AD4: 数量 | AE4: 数量 | AF4: 数量
A5: LAVA | B5: E6726LV-4GB | C5: Z33 | D5: CKD | E5: SP | F5: =#REF!+#REF!+#REF!+#REF!+#REF! -> #REF! | I5: 10000 | J5: 10000 | K5: 10000 | L5: 10000 | AE5: =G5+I5+K5+M5+O5+Q5+S5+U5+W5+Y5+AA5+AC5 -> 20000 | AF5: =H5+J5+L5+N5+P5+R5+T5+V5+X5+Z5+AB5+AD5 -> 20000
A6: LAVA | B6: E6759LV | D6: CKD | E6: SP | T6: 20000 | U6: 0 | V6: 500 | W6: 30000 | Y6: 20000 | AB6: 10000 | AC6: 30000 | AD6: 5000 | AE6: =G6+I6+K6+M6+O6+Q6+S6+U6+W6+Y6+AA6+AC6 -> 80000 | AF6: =H6+J6+L6+N6+P6+R6+T6+V6+X6+Z6+AB6+AD6 -> 35500
A7: LAVA | B7: E6726LV-3GB | C7: Yuva 3 pro | D7: CKD | E7: SP | F7: =#REF!+#REF!+#REF!+#REF!+#REF! -> #REF! | G7: 60000 | H7: 60000 | I7: 10000 | J7: 10000 | K7: 30000 | L7: 20000 | M7: 20000 | N7: 30000 | O7: 10000 | P7: 30000 | Q7: 10000 | R7: 20000 | S7: 0 | X7: 50000 | AE7: =G7+I7+K7+M7+O7+Q7+S7+U7+W7+Y7+AA7+AC7 -> 140000 | AF7: =H7+J7+L7+N7+P7+R7+T7+V7+X7+Z7+AB7+AD7 -> 220000
A8: LAVA | B8: E6727 | C8: Yuva Smart 2 | D8: CKD | E8: SP | F8: =#REF!+#REF!+#REF!+#REF!+#REF! -> #REF! | Q8: 30000 | S8: 70000 | V8: 80000 | W8: 30000 | X8: 40000 | Z8: 10000 | AA8: 30000 | AB8: 10000 | AD8: 10000 | AE8: =G8+I8+K8+M8+O8+Q8+S8+U8+W8+Y8+AA8+AC8 -> 160000 | AF8: =H8+J8+L8+N8+P8+R8+T8+V8+X8+Z8+AB8+AD8 -> 150000
A9: LAVA | B9: E6728LV | C9: Yuva 4 pro 5G | D9: CKD | E9: SP | F9: =#REF!+#REF!+#REF!+#REF!+#REF! -> #REF! | I9: 30000 | J9: 30000 | K9: 20000 | L9: 20000 | M9: 30000 | N9: 40000 | P9: 25000 | Q9: 20000 | R9: 20000 | S9: 0 | U9: 20000 | X9: 20000 | Y9: 10000 | AE9: =G9+I9+K9+M9+O9+Q9+S9+U9+W9+Y9+AA9+AC9 -> 130000 | AF9: =H9+J9+L9+N9+P9+R9+T9+V9+X9+Z9+AB9+AD9 -> 155000
A10: LAVA | B10: E6700LV | C10: Z34 | D10: CKD | E10: SP | F10: =#REF!+#REF!+#REF!+#REF!+#REF! -> #REF! | L10: 500 | M10: 10000 | N10: 19500 | O10: 40000 | P10: 40000 | R10: 30000 | S10: 30000 | T10: 40000 | V10: 80000 | W10: 20000 | X10: 90000 | Z10: 20000 | AB10: 20000 | AD10: 10000 | AE10: =G10+I10+K10+M10+O10+Q10+S10+U10+W10+Y10+AA10+AC10 -> 100000 | AF10: =H10+J10+L10+N10+P10+R10+T10+V10+X10+Z10+AB10+AD10 -> 350000
A11: LAVA | B11: 迭代 | D11: CKD | E11: SP | F11: =#REF!+#REF!+#REF!+#REF!+#REF! -> #REF! | U11: 0 | W11: 0 | Y11: 0 | AA11: 20000 | AC11: 30000 | AE11: =G11+I11+K11+M11+O11+Q11+S11+U11+W11+Y11+AA11+AC11 -> 50000 | AF11: =H11+J11+L11+N11+P11+R11+T11+V11+X11+Z11+AB11+AD11 -> 0
A12: LAVA | B12: E6570LV | D12: CKD | E12: SP | F12: =#REF!+#REF!+#REF!+#REF!+#REF! -> #REF! | U12: 20000 | W12: 100000 | Y12: 170000 | AA12: 200000 | AC12: 120000 | AE12: =G12+I12+K12+M12+O12+Q12+S12+U12+W12+Y12+AA12+AC12 -> 610000 | AF12: =H12+J12+L12+N12+P12+R12+T12+V12+X12+Z12+AB12+AD12 -> 0
A13: LAVA小计 | F13: =SUM(F5:F12) -> #REF! | G13: =SUM(G5:G12) -> 60000 | H13: =SUM(H5:H12) -> 60000 | I13: =SUM(I5:I12) -> 50000 | J13: =SUM(J5:J12) -> 50000 | K13: =SUM(K5:K12) -> 60000 | L13: =SUM(L5:L12) -> 50500 | M13: =SUM(M5:M12) -> 60000 | ... AD13: =SUM(AD5:AD12) -> 25000 | AE13: =G13+I13+K13+M13+O13+Q13+S13+U13+W13+Y13+AA13+AC13 -> 1290000 | AF13: =H13+J13+L13+N13+P13+R13+T13+V13+X13+Z13+AB13+AD13 -> 930500
A14: SM | B14: E6810SM | D14: SKD | E14: SP | F14: =#REF!+#REF!+#REF!+#REF!+#REF! -> #REF! | K14: 30000 | L14: 20000 | M14: 10000 | N14: 10000 | Q14: 20000 | AE14: =G14+I14+K14+M14+O14+Q14+S14+U14+W14+Y14+AA14+AC14 -> 60000 | AF14: =H14+J14+L14+N14+P14+R14+T14+V14+X14+Z14+AB14+AD14 -> 30000
A15: SM | B15: E6810SM-128GB | D15: SKD | E15: SP | F15: =#REF!+#REF!+#REF!+#REF!+#REF! -> #REF! | K15: 10000 | S15: 10000 | AE15: =G15+I15+K15+M15+O15+Q15+S15+U15+W15+Y15+AA15+AC15 -> 20000 | AF15: =H15+J15+L15+N15+P15+R15+T15+V15+X15+Z15+AB15+AD15 -> 0
A16: SM | B16: E6726SM | D16: SKD | E16: SP | F16: =#REF!+#REF!+#REF!+#REF!+#REF! -> #REF! | S16: 10000 | U16: 30000 | Y16: 20000 | AC16: 10000 | AE16: =G16+I16+K16+M16+O16+Q16+S16+U16+W16+Y16+AA16+AC16 -> 70000 | AF16: =H16+J16+L16+N16+P16+R16+T16+V16+X16+Z16+AB16+AD16 -> 0
A17: SM小计 | F17: =SUM(F14:F16) -> #REF! | G17: =SUM(G14:G16) -> 0 | H17: =SUM(H14:H16) -> 0 | I17: =SUM(I14:I16) -> 0 | J17: =SUM(J14:J16) -> 0 | K17: =SUM(K14:K16) -> 40000 | L17: =SUM(L14:L16) -> 20000 | M17: =SUM(M14:M16) -> 10000 | ... AA17: =SUM(AA14:AA16) -> 0 | AC17: =SUM(AC14:AC16) -> 10000 | AE17: =G17+I17+K17+M17+O17+Q17+S17+U17+W17+Y17+AA17+AC17 -> 150000 | AF17: =H17+J17+L17+N17+P17+R17+T17+V17+X17+Z17+AB17+AD17 -> 30000
A18: HMD | B18: E1885N-31E | C18: Crazy 5 | D18: CKD | E18: FP | F18: =#REF!+#REF!+#REF!+#REF!+#REF! -> #REF! | G18: 650000 | H18: 866750 | I18: 600000 | J18: 340200 | K18: 500000 | L18: 239000 | M18: 430000 | N18: 145750 | O18: 430000 | P18: 548750 | Q18: 430000 | R18: 245250 | S18: 580000 | T18: 332000 | U18: 600000 | V18: 207750 | W18: 650000 | X18: 435250 | Y18: 650000 | Z18: 487000 | AA18: 350000 | AB18: 439500 | AC18: 350000 | AD18: 557375 | AE18: =G18+I18+K18+M18+O18+Q18+S18+U18+W18+Y18+AA18+AC18 -> 6220000 | AF18: =H18+J18+L18+N18+P18+R18+T18+V18+X18+Z18+AB18+AD18 -> 4844575
A19: HMD | B19: E1889/1890 | C19: LedaS | D19: CKD | E19: FP | F19: =#REF!+#REF!+#REF!+#REF!+#REF! -> #REF! | G19: 270000 | H19: 270000 | I19: 250000 | J19: 235500 | K19: 250000 | M19: 250000 | N19: 122500 | O19: 250000 | P19: 265000 | Q19: 250000 | R19: 229000 | S19: 250000 | T19: 144000 | U19: 250000 | V19: 113000 | W19: 250000 | X19: 218000 | Y19: 250000 | Z19: 361000 | AA19: 200000 | AB19: 367000 | AC19: 200000 | AD19: 361000 | AE19: =G19+I19+K19+M19+O19+Q19+S19+U19+W19+Y19+AA19+AC19 -> 2920000 | AF19: =H19+J19+L19+N19+P19+R19+T19+V19+X19+Z19+AB19+AD19 -> 2686000
A20: HMD | B20: E2001H | C20: VOX | D20: CKD | E20: FP | G20: 480000 | H20: 411512 | I20: 300000 | J20: 226796 | K20: 300000 | L20: 428412 | M20: 280000 | N20: 407968 | O20: 450000 | P20: 173800 | Q20: 400000 | R20: 176032 | S20: 400000 | T20: 285912 | U20: 400000 | V20: 329784 | W20: 400000 | X20: 340896 | Y20: 400000 | Z20: 303476 | AA20: 140000 | AB20: 471976 | AC20: 140000 | AD20: 427128 | AE20: =G20+I20+K20+M20+O20+Q20+S20+U20+W20+Y20+AA20+AC20 -> 4090000 | AF20: =H20+J20+L20+N20+P20+R20+T20+V20+X20+Z20+AB20+AD20 -> 3983692
A21: HMD | B21: E2447 | C21: Frodo | D21: CKD | E21: FP | G21: 60000 | H21: 60000 | I21: 100000 | J21: 92880 | K21: 100000 | L21: 206360 | M21: 140000 | N21: 145160 | O21: 140000 | P21: 72440 | Q21: 140000 | R21: 73280 | S21: 140000 | T21: 41520 | U21: 140000 | V21: 18400 | W21: 140000 | X21: 18000 | Y21: 140000 | Z21: 39540 | AA21: 100000 | AB21: 83720 | AC21: 100000 | AD21: 99120 | AE21: =G21+I21+K21+M21+O21+Q21+S21+U21+W21+Y21+AA21+AC21 -> 1440000 | AF21: =H21+J21+L21+N21+P21+R21+T21+V21+X21+Z21+AB21+AD21 -> 950420
A22: HMD | B22: P2000 | C22: Leia | D22: CKD | E22: FP | P22: 11500 | Q22: 30000 | S22: 120000 | T22: 48112 | U22: 120000 | V22: 15768 | W22: 120000 | X22: 40304 | Y22: 120000 | Z22: 28600 | AA22: 120000 | AB22: 63888 | AC22: 113000 | AD22: 53396 | AE22: =G22+I22+K22+M22+O22+Q22+S22+U22+W22+Y22+AA22+AC22 -> 743000 | AF22: =H22+J22+L22+N22+P22+R22+T22+V22+X22+Z22+AB22+AD22 -> 261568
A23: HMD小计 | F23: =SUM(F18:F22) -> #REF! | G23: =SUM(G18:G22) -> 1460000 | H23: =SUM(H18:H22) -> 1608262 | I23: =SUM(I18:I22) -> 1250000 | J23: =SUM(J18:J22) -> 895376 | K23: =SUM(K18:K22) -> 1150000 | L23: =SUM(L18:L22) -> 873772 | M23: =SUM(M18:M22) -> 1100000 | ... AD23: =SUM(AD18:AD22) -> 1498019 | AE23: =G23+I23+K23+M23+O23+Q23+S23+U23+W23+Y23+AA23+AC23 -> 15413000 | AF23: =H23+J23+L23+N23+P23+R23+T23+V23+X23+Z23+AB23+AD23 -> 12726255
A24: BLU | B24: PD6703TF | C24: B170D | D24: CBU | E24: SP | L24: 0 | M24: 0 | N24: 0 | P24: 41000 | R24: 30000 | T24: 70000 | V24: 20000 | X24: 10000 | Z24: 50000 | AB24: 45000 | AD24: 30000 | AE24: =G24+I24+K24+M24+O24+Q24+S24+U24+W24+Y24+AA24+AC24 -> 0 | AF24: =H24+J24+L24+N24+P24+R24+T24+V24+X24+Z24+AB24+AD24 -> 296000
A25: BLU | B25: E6726BL | C25: K5 | D25: CBU | E25: SP | G25: 10000 | H25: 10000 | I25: 10000 | J25: 0 | L25: 10000 | O25: 10000 | Q25: 0 | S25: 10000 | U25: 0 | W25: 10000 | AE25: =G25+I25+K25+M25+O25+Q25+S25+U25+W25+Y25+AA25+AC25 -> 50000 | AF25: =H25+J25+L25+N25+P25+R25+T25+V25+X25+Z25+AB25+AD25 -> 20000
A26: BLU | B26: E6733BL | C26: K20 | D26: CBU | E26: SP | G26: 10000 | H26: 10000 | I26: 10000 | J26: 0 | L26: 10000 | Q26: 10000 | U26: 10000 | AE26: =G26+I26+K26+M26+O26+Q26+S26+U26+W26+Y26+AA26+AC26 -> 40000 | AF26: =H26+J26+L26+N26+P26+R26+T26+V26+X26+Z26+AB26+AD26 -> 20000
A27: BLU | B27: E6730BL | C27: K30 | D27: CBU | E27: SP | G27: 6000 | H27: 5980 | I27: 4000 | L27: 4020 | Q27: 10000 | AE27: =G27+I27+K27+M27+O27+Q27+S27+U27+W27+Y27+AA27+AC27 -> 20000 | AF27: =H27+J27+L27+N27+P27+R27+T27+V27+X27+Z27+AB27+AD27 -> 10000
A28: BLU | B28: E6810 | D28: CBU | E28: SP | O28: 10000 | U28: 10000 | Y28: 10000 | AC28: 10000 | AE28: =G28+I28+K28+M28+O28+Q28+S28+U28+W28+Y28+AA28+AC28 -> 40000 | AF28: =H28+J28+L28+N28+P28+R28+T28+V28+X28+Z28+AB28+AD28 -> 0
A29: BLU小计 | F29: =SUM(F24:F24) -> 0 | G29: =SUM(G24:G28) -> 26000 | H29: =SUM(H24:H28) -> 25980 | I29: =SUM(I24:I28) -> 24000 | J29: =SUM(J24:J28) -> 0 | K29: =SUM(K24:K28) -> 0 | L29: =SUM(L24:L28) -> 24020 | M29: =SUM(M24:M28) -> 0 | N29: =SUM(N24:N28) -> 0 | ... AD29: =SUM(AD24:AD28) -> 30000 | AE29: =G29+I29+K29+M29+O29+Q29+S29+U29+W29+Y29+AA29+AC29 -> 150000 | AF29: =H29+J29+L29+N29+P29+R29+T29+V29+X29+Z29+AB29+AD29 -> 346000
A30: LF | B30: E6726LF | C30: HERO | D30: CBU | E30: SP | G30: 10000 | H30: 10000 | M30: 10000 | P30: 5000 | Q30: 10000 | U30: 10000 | Z30: 10000 | AE30: =G30+I30+K30+M30+O30+Q30+S30+U30+W30+Y30+AA30+AC30 -> 40000 | AF30: =H30+J30+L30+N30+P30+R30+T30+V30+X30+Z30+AB30+AD30 -> 25000
A31: LF | B31: E6733LF | C31: IDOL | D31: CBU | E31: SP | G31: 10000 | H31: 10000 | O31: 10000 | S31: 10000 | AE31: =G31+I31+K31+M31+O31+Q31+S31+U31+W31+Y31+AA31+AC31 -> 30000 | AF31: =H31+J31+L31+N31+P31+R31+T31+V31+X31+Z31+AB31+AD31 -> 10000
A32: LF | B32: E6730LF | C32: STAR | D32: CBU | E32: SP | G32: 3000 | H32: 3000 | I32: 7000 | K32: 7000 | Q32: 10000 | AE32: =G32+I32+K32+M32+O32+Q32+S32+U32+W32+Y32+AA32+AC32 -> 27000 | AF32: =H32+J32+L32+N32+P32+R32+T32+V32+X32+Z32+AB32+AD32 -> 3000
A33: LF | B33: E6707LF | C33: VISION | D33: CBU | E33: SP | G33: 1500 | H33: 1500 | I33: 8500 | K33: 8500 | Q33: 10000 | AE33: =G33+I33+K33+M33+O33+Q33+S33+U33+W33+Y33+AA33+AC33 -> 28500 | AF33: =H33+J33+L33+N33+P33+R33+T33+V33+X33+Z33+AB33+AD33 -> 1500
A34: LF | B34: E6810LF | C34: SIMPLE | D34: CBU | E34: SP | O34: 10000 | R34: 12000 | T34: 3000 | U34: 10000 | Y34: 10000 | Z34: 10000 | AE34: =G34+I34+K34+M34+O34+Q34+S34+U34+W34+Y34+AA34+AC34 -> 30000 | AF34: =H34+J34+L34+N34+P34+R34+T34+V34+X34+Z34+AB34+AD34 -> 25000
A35: LF小计 | F35: =SUM(F30:F30) -> 0 | G35: =SUM(G30:G34) -> 24500 | H35: =SUM(H30:H34) -> 24500 | I35: =SUM(I30:I34) -> 15500 | J35: =SUM(J30:J34) -> 0 | K35: =SUM(K30:K34) -> 15500 | L35: =SUM(L30:L34) -> 0 | M35: =SUM(M30:M34) -> 10000 | N35: =SUM(N30:N34) -> 0 | ... U35: =SUM(U30:U34) -> 20000 | W35: =SUM(W30:W34) -> 0 | Y35: =SUM(Y30:Y34) -> 10000 | Z35: =SUM(Z30:Z34) -> 20000 | AA35: =SUM(AA30:AA34) -> 0 | AC35: =SUM(AC30:AC34) -> 0 | AE35: =G35+I35+K35+M35+O35+Q35+S35+U35+W35+Y35+AA35+AC35 -> 155500 | AF35: =H35+J35+L35+N35+P35+R35+T35+V35+X35+Z35+AB35+AD35 -> 64500
A36: Mobicel | B36: E5042MBC | C36: F51 | D36: SKD | E36: SP | F36: =#REF!+#REF!+#REF!+#REF!+#REF! -> #REF! | G36: 20000 | H36: 20000 | K36: 32500 | L36: 32500 | N36: 20000 | O36: 20000 | P36: 15000 | R36: 35000 | S36: 20000 | AE36: =G36+I36+K36+M36+O36+Q36+S36+U36+W36+Y36+AA36+AC36 -> 92500 | AF36: =H36+J36+L36+N36+P36+R36+T36+V36+X36+Z36+AB36+AD36 -> 122500
A37: Mobicel | B37: E6731MBC | C37: X7 | D37: SKD | E37: SP | F37: =#REF!+#REF!+#REF!+#REF!+#REF! -> #REF! | G37: 10000 | H37: 10800 | O37: 20000 | S37: 20000 | W37: 10000 | AE37: =G37+I37+K37+M37+O37+Q37+S37+U37+W37+Y37+AA37+AC37 -> 60000 | AF37: =H37+J37+L37+N37+P37+R37+T37+V37+X37+Z37+AB37+AD37 -> 10800
A38: Mobicel小计 | F38: =SUM(F36:F37) -> #REF! | G38: =SUM(G36:G37) -> 30000 | H38: =SUM(H36:H37) -> 30800 | I38: =SUM(I36:I37) -> 0 | J38: =SUM(J36:J37) -> 0 | K38: =SUM(K36:K37) -> 32500 | L38: =SUM(L36:L37) -> 32500 | M38: =SUM(M36:M37) -> 0 | ... S38: =SUM(S36:S37) -> 40000 | U38: =SUM(U36:U37) -> 0 | W38: =SUM(W36:W37) -> 10000 | X38: =SUM(X36:X37) -> 0 | Y38: =SUM(Y36:Y37) -> 0 | Z38: =SUM(Z36:Z37) -> 0 | AA38: =SUM(AA36:AA37) -> 0 | AB38: =SUM(AB36:AB37) -> 0 | AC38: =SUM(AC36:AC37) -> 0 | AE38: =G38+I38+K38+M38+O38+Q38+S38+U38+W38+Y38+AA38+AC38 -> 152500 | AF38: =H38+J38+L38+N38+P38+R38+T38+V38+X38+Z38+AB38+AD38 -> 133300
A39: XM | B39: E6707XM | C39: Ultra 8 | D39: SKD | E39: SP | G39: 3030 | H39: 3030 | AE39: =G39+I39+K39+M39+O39+Q39+S39+U39+W39+Y39+AA39+AC39 -> 3030 | AF39: =H39+J39+L39+N39+P39+R39+T39+V39+X39+Z39+AB39+AD39 -> 3030
A40: XM | B40: E6707XM Pro | C40: Ultra 8 Pro | D40: SKD | E40: SP | G40: 3030 | H40: 3030 | AE40: =G40+I40+K40+M40+O40+Q40+S40+U40+W40+Y40+AA40+AC40 -> 3030 | AF40: =H40+J40+L40+N40+P40+R40+T40+V40+X40+Z40+AB40+AD40 -> 3030
...

Sheet 数量汇总
B2: 客户 | C2: 2025年
C3: 1月分解 | D3: 1月实际 | E3: 2月分解 | F3: 2月实际 | G3: 3月分解 | H3: 3月实际 | I3: 4月分解 | J3: 4月实际 | K3: 5月分解 | L3: 5月实际 | M3: 6月分解 | N3: 6月实际 | O3: 7月分解 | P3: 7月实际 | Q3: 8月分解 | R3: 8月实际 | S3: 9月分解 | T3: 9月实际 | U3: 10月分解 | V3: 10月实际 | W3: 11月分解 | X3: 11月实际 | Y3: 12月分解 | Z3: 12月实际 | AA3: 全年分解目标 | AB3: 全年已完成
B4: LAVA | C4: =SUMIF('手机&平板保底版销售计划数量VS 实际出货'!A:A,B4,'手机&平板保底版销售计划数量VS 实际出货'!G:G) -> 60000 | D4: =SUMIF('手机&平板保底版销售计划数量VS 实际出货'!A:A,B4,'手机&平板保底版销售计划数量VS 实际出货'!H:H) -> 60000 | E4: =SUMIF('手机&平板保底版销售计划数量VS 实际出货'!A:A,B4,'手机&平板保底版销售计划数量VS 实际出货'!I:I) -> 50000 | F4: =SUMIF('手机&平板保底版销售计划数量VS 实际出货'!A:A,B4,'手机&平板保底版销售计划数量VS 实际出货'!J:J) -> 50000 | G4: =SUMIF('手机&平板保底版销售计划数量VS 实际出货'!A:A,B4,'手机&平板保底版销售计划数量VS 实际出货'!K:K) -> 60000 | H4: =SUMIF('手机&平板保底版销售计划数量VS 实际出货'!A:A,B4,'手机&平板保底版销售计划数量VS 实际出货'!L:L) -> 50500 | I4: =SUMIF('手机&平板保底版销售计划数量VS 实际出货'!A:A,B4,'手机&平板保底版销售计划数量VS 实际出货'!M:M) -> 60000 | J4: =SUMIF('手机&平板保底版销售计划数量VS 实际出货'!A:A,B4,'手机&平板保底版销售计划数量VS 实际出货'!N:N) -> 89500 | K4: =SUMIF('手机&平板保底版销售计划数量VS 实际出货'!A:A,B4,'手机&平板保底版销售计划数量VS 实际出货'!O:O) -> 50000 | L4: =SUMIF('手机&平板保底版销售计划数量VS 实际出货'!A:A,B4,'手机&平板保底版销售计划数量VS 实际出货'!P:P) -> 95000 | M4: =SUMIF('手机&平板保底版销售计划数量VS 实际出货'!A:A,B4,'手机&平板保底版销售计划数量VS 实际出货'!Q:Q) -> 60000 | N4: =SUMIF('手机&平板保底版销售计划数量VS 实际出货'!A:A,B4,'手机&平板保底版销售计划数量VS 实际出货'!R:R) -> 70000 | O4: =SUMIF('手机&平板保底版销售计划数量VS 实际出货'!A:A,B4,'手机&平板保底版销售计划数量VS 实际出货'!S:S) -> 100000 | P4: =SUMIF('手机&平板保底版销售计划数量VS 实际出货'!A:A,B4,'手机&平板保底版销售计划数量VS 实际出货'!T:T) -> 60000 | Q4: =SUMIF('手机&平板保底版销售计划数量VS 实际出货'!A:A,B4,'手机&平板保底版销售计划数量VS 实际出货'!U:U) -> 40000 | R4: =SUMIF('手机&平板保底版销售计划数量VS 实际出货'!A:A,B4,'手机&平板保底版销售计划数量VS 实际出货'!V:V) -> 160500 | S4: =SUMIF('手机&平板保底版销售计划数量VS 实际出货'!A:A,B4,'手机&平板保底版销售计划数量VS 实际出货'!W:W) -> 180000 | T4: =SUMIF('手机&平板保底版销售计划数量VS 实际出货'!A:A,B4,'手机&平板保底版销售计划数量VS 实际出货'!X:X) -> 200000 | U4: =SUMIF('手机&平板保底版销售计划数量VS 实际出货'!A:A,B4,'手机&平板保底版销售计划数量VS 实际出货'!Y:Y) -> 200000 | V4: =SUMIF('手机&平板保底版销售计划数量VS 实际出货'!A:A,B4,'手机&平板保底版销售计划数量VS 实际出货'!Z:Z) -> 30000 | W4: =SUMIF('手机&平板保底版销售计划数量VS 实际出货'!A:A,B4,'手机&平板保底版销售计划数量VS 实际出货'!AA:AA) -> 250000 | X4: =SUMIF('手机&平板保底版销售计划数量VS 实际出货'!A:A,B4,'手机&平板保底版销售计划数量VS 实际出货'!AB:AB) -> 40000 | Y4: =SUMIF('手机&平板保底版销售计划数量VS 实际出货'!A:A,B4,'手机&平板保底版销售计划数量VS 实际出货'!AC:AC) -> 180000 | Z4: =SUMIF('手机&平板保底版销售计划数量VS 实际出货'!A:A,B4,'手机&平板保底版销售计划数量VS 实际出货'!AD:AD) -> 25000 | AA4: =C4+E4+G4+I4+K4+M4+O4+Q4+S4+U4+W4+Y4 -> 1290000 | AB4: =D4+F4+H4+J4+L4+N4+P4+R4+T4+V4+X4+Z4 -> 930500
B5: HMD | C5: =SUMIF('手机&平板保底版销售计划数量VS 实际出货'!A:A,B5,'手机&平板保底版销售计划数量VS 实际出货'!G:G) -> 1460000 | D5: =SUMIF('手机&平板保底版销售计划数量VS 实际出货'!A:A,B5,'手机&平板保底版销售计划数量VS 实际出货'!H:H) -> 1608262 | E5: =SUMIF('手机&平板保底版销售计划数量VS 实际出货'!A:A,B5,'手机&平板保底版销售计划数量VS 实际出货'!I:I) -> 1250000 | F5: =SUMIF('手机&平板保底版销售计划数量VS 实际出货'!A:A,B5,'手机&平板保底版销售计划数量VS 实际出货'!J:J) -> 895376 | G5: =SUMIF('手机&平板保底版销售计划数量VS 实际出货'!A:A,B5,'手机&平板保底版销售计划数量VS 实际出货'!K:K) -> 1150000 | H5: =SUMIF('手机&平板保底版销售计划数量VS 实际出货'!A:A,B5,'手机&平板保底版销售计划数量VS 实际出货'!L:L) -> 873772 | I5: =SUMIF('手机&平板保底版销售计划数量VS 实际出货'!A:A,B5,'手机&平板保底版销售计划数量VS 实际出货'!M:M) -> 1100000 | J5: =SUMIF('手机&平板保底版销售计划数量VS 实际出货'!A:A,B5,'手机&平板保底版销售计划数量VS 实际出货'!N:N) -> 821378 | K5: =SUMIF('手机&平板保底版销售计划数量VS 实际出货'!A:A,B5,'手机&平板保底版销售计划数量VS 实际出货'!O:O) -> 1270000 | L5: =SUMIF('手机&平板保底版销售计划数量VS 实际出货'!A:A,B5,'手机&平板保底版销售计划数量VS 实际出货'!P:P) -> 1071490 | M5: =SUMIF('手机&平板保底版销售计划数量VS 实际出货'!A:A,B5,'手机&平板保底版销售计划数量VS 实际出货'!Q:Q) -> 1250000 | N5: =SUMIF('手机&平板保底版销售计划数量VS 实际出货'!A:A,B5,'手机&平板保底版销售计划数量VS 实际出货'!R:R) -> 723562 | O5: =SUMIF('手机&平板保底版销售计划数量VS 实际出货'!A:A,B5,'手机&平板保底版销售计划数量VS 实际出货'!S:S) -> 1490000 | P5: =SUMIF('手机&平板保底版销售计划数量VS 实际出货'!A:A,B5,'手机&平板保底版销售计划数量VS 实际出货'!T:T) -> 851544 | Q5: =SUMIF('手机&平板保底版销售计划数量VS 实际出货'!A:A,B5,'手机&平板保底版销售计划数量VS 实际出货'!U:U) -> 1510000 | R5: =SUMIF('手机&平板保底版销售计划数量VS 实际出货'!A:A,B5,'手机&平板保底版销售计划数量VS 实际出货'!V:V) -> 684702 | S5: =SUMIF('手机&平板保底版销售计划数量VS 实际出货'!A:A,B5,'手机&平板保底版销售计划数量VS 实际出货'!W:W) -> 1560000 | T5: =SUMIF('手机&平板保底版销售计划数量VS 实际出货'!A:A,B5,'手机&平板保底版销售计划数量VS 实际出货'!X:X) -> 1052450 | U5: =SUMIF('手机&平板保底版销售计划数量VS 实际出货'!A:A,B5,'手机&平板保底版销售计划数量VS 实际出货'!Y:Y) -> 1560000 | V5: =SUMIF('手机&平板保底版销售计划数量VS 实际出货'!A:A,B5,'手机&平板保底版销售计划数量VS 实际出货'!Z:Z) -> 1219616 | W5: =SUMIF('手机&平板保底版销售计划数量VS 实际出货'!A:A,B5,'手机&平板保底版销售计划数量VS 实际出货'!AA:AA) -> 910000 | X5: =SUMIF('手机&平板保底版销售计划数量VS 实际出货'!A:A,B5,'手机&平板保底版销售计划数量VS 实际出货'!AB:AB) -> 1426084 | Y5: =SUMIF('手机&平板保底版销售计划数量VS 实际出货'!A:A,B5,'手机&平板保底版销售计划数量VS 实际出货'!AC:AC) -> 903000 | Z5: =SUMIF('手机&平板保底版销售计划数量VS 实际出货'!A:A,B5,'手机&平板保底版销售计划数量VS 实际出货'!AD:AD) -> 1498019 | AA5: =C5+E5+G5+I5+K5+M5+O5+Q5+S5+U5+W5+Y5 -> 15413000 | AB5: =D5+F5+H5+J5+L5+N5+P5+R5+T5+V5+X5+Z5 -> 12726255
B6: ZTE | C6: =SUMIF('手机&平板保底版销售计划数量VS 实际出货'!A:A,B6,'手机&平板保底版销售计划数量VS 实际出货'!G:G) -> 411243 | D6: =SUMIF('手机&平板保底版销售计划数量VS 实际出货'!A:A,B6,'手机&平板保底版销售计划数量VS 实际出货'!H:H) -> 376437 | E6: =SUMIF('手机&平板保底版销售计划数量VS 实际出货'!A:A,B6,'手机&平板保底版销售计划数量VS 实际出货'!I:I) -> 233544 | F6: =SUMIF('手机&平板保底版销售计划数量VS 实际出货'!A:A,B6,'手机&平板保底版销售计划数量VS 实际出货'!J:J) -> 288076 | G6: =SUMIF('手机&平板保底版销售计划数量VS 实际出货'!A:A,B6,'手机&平板保底版销售计划数量VS 实际出货'!K:K) -> 422713 | H6: =SUMIF('手机&平板保底版销售计划数量VS 实际出货'!A:A,B6,'手机&平板保底版销售计划数量VS 实际出货'!L:L) -> 359089 | I6: =SUMIF('手机&平板保底版销售计划数量VS 实际出货'!A:A,B6,'手机&平板保底版销售计划数量VS 实际出货'!M:M) -> 219258 | J6: =SUMIF('手机&平板保底版销售计划数量VS 实际出货'!A:A,B6,'手机&平板保底版销售计划数量VS 实际出货'!N:N) -> 294752 | K6: =SUMIF('手机&平板保底版销售计划数量VS 实际出货'!A:A,B6,'手机&平板保底版销售计划数量VS 实际出货'!O:O) -> 750000 | L6: =SUMIF('手机&平板保底版销售计划数量VS 实际出货'!A:A,B6,'手机&平板保底版销售计划数量VS 实际出货'!P:P) -> 509025 | M6: =SUMIF('手机&平板保底版销售计划数量VS 实际出货'!A:A,B6,'手机&平板保底版销售计划数量VS 实际出货'!Q:Q) -> 650000 | N6: =SUMIF('手机&平板保底版销售计划数量VS 实际出货'!A:A,B6,'手机&平板保底版销售计划数量VS 实际出货'!R:R) -> 541095 | O6: =SUMIF('手机&平板保底版销售计划数量VS 实际出货'!A:A,B6,'手机&平板保底版销售计划数量VS 实际出货'!S:S) -> 850000 | P6: =SUMIF('手机&平板保底版销售计划数量VS 实际出货'!A:A,B6,'手机&平板保底版销售计划数量VS 实际出货'!T:T) -> 608378 | Q6: =SUMIF('手机&平板保底版销售计划数量VS 实际出货'!A:A,B6,'手机&平板保底版销售计划数量VS 实际出货'!U:U) -> 1050000 | R6: =SUMIF('手机&平板保底版销售计划数量VS 实际出货'!A:A,B6,'手机&平板保底版销售计划数量VS 实际出货'!V:V) -> 576035 | S6: =SUMIF('手机&平板保底版销售计划数量VS 实际出货'!A:A,B6,'手机&平板保底版销售计划数量VS 实际出货'!W:W) -> 967422 | T6: =SUMIF('手机&平板保底版销售计划数量VS 实际出货'!A:A,B6,'手机&平板保底版销售计划数量VS 实际出货'!X:X) -> 952732 | U6: =SUMIF('手机&平板保底版销售计划数量VS 实际出货'!A:A,B6,'手机&平板保底版销售计划数量VS 实际出货'!Y:Y) -> 950000 | V6: =SUMIF('手机&平板保底版销售计划数量VS 实际出货'!A:A,B6,'手机&平板保底版销售计划数量VS 实际出货'!Z:Z) -> 621317 | W6: =SUMIF('手机&平板保底版销售计划数量VS 实际出货'!A:A,B6,'手机&平板保底版销售计划数量VS 实际出货'!AA:AA) -> 800000 | X6: =SUMIF('手机&平板保底版销售计划数量VS 实际出货'!A:A,B6,'手机&平板保底版销售计划数量VS 实际出货'!AB:AB) -> 728571 | Y6: =SUMIF('手机&平板保底版销售计划数量VS 实际出货'!A:A,B6,'手机&平板保底版销售计划数量VS 实际出货'!AC:AC) -> 854050 | Z6: =SUMIF('手机&平板保底版销售计划数量VS 实际出货'!A:A,B6,'手机&平板保底版销售计划数量VS 实际出货'!AD:AD) -> 815609 | AA6: =C6+E6+G6+I6+K6+M6+O6+Q6+S6+U6+W6+Y6 -> 8158230 | AB6: =D6+F6+H6+J6+L6+N6+P6+R6+T6+V6+X6+Z6 -> 6671116
B7: XM | C7: =SUMIF('手机&平板保底版销售计划数量VS 实际出货'!A:A,B7,'手机&平板保底版销售计划数量VS 实际出货'!G:G) -> 14140 | D7: =SUMIF('手机&平板保底版销售计划数量VS 实际出货'!A:A,B7,'手机&平板保底版销售计划数量VS 实际出货'!H:H) -> 14140 | E7: =SUMIF('手机&平板保底版销售计划数量VS 实际出货'!A:A,B7,'手机&平板保底版销售计划数量VS 实际出货'!I:I) -> 0 | F7: =SUMIF('手机&平板保底版销售计划数量VS 实际出货'!A:A,B7,'手机&平板保底版销售计划数量VS 实际出货'!J:J) -> 0 | G7: =SUMIF('手机&平板保底版销售计划数量VS 实际出货'!A:A,B7,'手机&平板保底版销售计划数量VS 实际出货'!K:K) -> 0 | H7: =SUMIF('手机&平板保底版销售计划数量VS 实际出货'!A:A,B7,'手机&平板保底版销售计划数量VS 实际出货'!L:L) -> 0 | I7: =SUMIF('手机&平板保底版销售计划数量VS 实际出货'!A:A,B7,'手机&平板保底版销售计划数量VS 实际出货'!M:M) -> 0 | J7: =SUMIF('手机&平板保底版销售计划数量VS 实际出货'!A:A,B7,'手机&平板保底版销售计划数量VS 实际出货'!N:N) -> 0 | K7: =SUMIF('手机&平板保底版销售计划数量VS 实际出货'!A:A,B7,'手机&平板保底版销售计划数量VS 实际出货'!O:O) -> 10000 | L7: =SUMIF('手机&平板保底版销售计划数量VS 实际出货'!A:A,B7,'手机&平板保底版销售计划数量VS 实际出货'!P:P) -> 0 | M7: =SUMIF('手机&平板保底版销售计划数量VS 实际出货'!A:A,B7,'手机&平板保底版销售计划数量VS 实际出货'!Q:Q) -> 20000 | N7: =SUMIF('手机&平板保底版销售计划数量VS 实际出货'!A:A,B7,'手机&平板保底版销售计划数量VS 实际出货'!R:R) -> 0 | O7: =SUMIF('手机&平板保底版销售计划数量VS 实际出货'!A:A,B7,'手机&平板保底版销售计划数量VS 实际出货'!S:S) -> 20000 | P7: =SUMIF('手机&平板保底版销售计划数量VS 实际出货'!A:A,B7,'手机&平板保底版销售计划数量VS 实际出货'!T:T) -> 0 | Q7: =SUMIF('手机&平板保底版销售计划数量VS 实际出货'!A:A,B7,'手机&平板保底版销售计划数量VS 实际出货'!U:U) -> 10000 | R7: =SUMIF('手机&平板保底版销售计划数量VS 实际出货'!A:A,B7,'手机&平板保底版销售计划数量VS 实际出货'!V:V) -> 0 | S7: =SUMIF('手机&平板保底版销售计划数量VS 实际出货'!A:A,B7,'手机&平板保底版销售计划数量VS 实际出货'!W:W) -> 20000 | T7: =SUMIF('手机&平板保底版销售计划数量VS 实际出货'!A:A,B7,'手机&平板保底版销售计划数量VS 实际出货'!X:X) -> 0 | U7: =SUMIF('手机&平板保底版销售计划数量VS 实际出货'!A:A,B7,'手机&平板保底版销售计划数量VS 实际出货'!Y:Y) -> 10000 | V7: =SUMIF('手机&平板保底版销售计划数量VS 实际出货'!A:A,B7,'手机&平板保底版销售计划数量VS 实际出货'!Z:Z) -> 0 | W7: =SUMIF('手机&平板保底版销售计划数量VS 实际出货'!A:A,B7,'手机&平板保底版销售计划数量VS 实际出货'!AA:AA) -> 20000 | X7: =SUMIF('手机&平板保底版销售计划数量VS 实际出货'!A:A,B7,'手机&平板保底版销售计划数量VS 实际出货'!AB:AB) -> 5050 | Y7: =SUMIF('手机&平板保底版销售计划数量VS 实际出货'!A:A,B7,'手机&平板保底版销售计划数量VS 实际出货'!AC:AC) -> 10000 | Z7: =SUMIF('手机&平板保底版销售计划数量VS 实际出货'!A:A,B7,'手机&平板保底版销售计划数量VS 实际出货'!AD:AD) -> 5050 | AA7: =C7+E7+G7+I7+K7+M7+O7+Q7+S7+U7+W7+Y7 -> 134140 | AB7: =D7+F7+H7+J7+L7+N7+P7+R7+T7+V7+X7+Z7 -> 24240
B8: SM | C8: =SUMIF('手机&平板保底版销售计划数量VS 实际出货'!A:A,B8,'手机&平板保底版销售计划数量VS 实际出货'!G:G) -> 0 | D8: =SUMIF('手机&平板保底版销售计划数量VS 实际出货'!A:A,B8,'手机&平板保底版销售计划数量VS 实际出货'!H:H) -> 0 | E8: =SUMIF('手机&平板保底版销售计划数量VS 实际出货'!A:A,B8,'手机&平板保底版销售计划数量VS 实际出货'!I:I) -> 0 | F8: =SUMIF('手机&平板保底版销售计划数量VS 实际出货'!A:A,B8,'手机&平板保底版销售计划数量VS 实际出货'!J:J) -> 0 | G8: =SUMIF('手机&平板保底版销售计划数量VS 实际出货'!A:A,B8,'手机&平板保底版销售计划数量VS 实际出货'!K:K) -> 40000 | H8: =SUMIF('手机&平板保底版销售计划数量VS 实际出货'!A:A,B8,'手机&平板保底版销售计划数量VS 实际出货'!L:L) -> 20000 | I8: =SUMIF('手机&平板保底版销售计划数量VS 实际出货'!A:A,B8,'手机&平板保底版销售计划数量VS 实际出货'!M:M) -> 10000 | J8: =SUMIF('手机&平板保底版销售计划数量VS 实际出货'!A:A,B8,'手机&平板保底版销售计划数量VS 实际出货'!N:N) -> 10000 | K8: =SUMIF('手机&平板保底版销售计划数量VS 实际出货'!A:A,B8,'手机&平板保底版销售计划数量VS 实际出货'!O:O) -> 0 | L8: =SUMIF('手机&平板保底版销售计划数量VS 实际出货'!A:A,B8,'手机&平板保底版销售计划数量VS 实际出货'!P:P) -> 0 | M8: =SUMIF('手机&平板保底版销售计划数量VS 实际出货'!A:A,B8,'手机&平板保底版销售计划数量VS 实际出货'!Q:Q) -> 20000 | N8: =SUMIF('手机&平板保底版销售计划数量VS 实际出货'!A:A,B8,'手机&平板保底版销售计划数量VS 实际出货'!R:R) -> 0 | O8: =SUMIF('手机&平板保底版销售计划数量VS 实际出货'!A:A,B8,'手机&平板保底版销售计划数量VS 实际出货'!S:S) -> 20000 | P8: =SUMIF('手机&平板保底版销售计划数量VS 实际出货'!A:A,B8,'手机&平板保底版销售计划数量VS 实际出货'!T:T) -> 0 | Q8: =SUMIF('手机&平板保底版销售计划数量VS 实际出货'!A:A,B8,'手机&平板保底版销售计划数量VS 实际出货'!U:U) -> 30000 | R8: =SUMIF('手机&平板保底版销售计划数量VS 实际出货'!A:A,B8,'手机&平板保底版销售计划数量VS 实际出货'!V:V) -> 0 | S8: =SUMIF('手机&平板保底版销售计划数量VS 实际出货'!A:A,B8,'手机&平板保底版销售计划数量VS 实际出货'!W:W) -> 0 | T8: =SUMIF('手机&平板保底版销售计划数量VS 实际出货'!A:A,B8,'手机&平板保底版销售计划数量VS 实际出货'!X:X) -> 0 | U8: =SUMIF('手机&平板保底版销售计划数量VS 实际出货'!A:A,B8,'手机&平板保底版销售计划数量VS 实际出货'!Y:Y) -> 20000 | V8: =SUMIF('手机&平板保底版销售计划数量VS 实际出货'!A:A,B8,'手机&平板保底版销售计划数量VS 实际出货'!Z:Z) -> 0 | W8: =SUMIF('手机&平板保底版销售计划数量VS 实际出货'!A:A,B8,'手机&平板保底版销售计划数量VS 实际出货'!AA:AA) -> 0 | X8: =SUMIF('手机&平板保底版销售计划数量VS 实际出货'!A:A,B8,'手机&平板保底版销售计划数量VS 实际出货'!AB:AB) -> 0 | Y8: =SUMIF('手机&平板保底版销售计划数量VS 实际出货'!A:A,B8,'手机&平板保底版销售计划数量VS 实际出货'!AC:AC) -> 10000 | Z8: =SUMIF('手机&平板保底版销售计划数量VS 实际出货'!A:A,B8,'手机&平板保底版销售计划数量VS 实际出货'!AD:AD) -> 0 | AA8: =C8+E8+G8+I8+K8+M8+O8+Q8+S8+U8+W8+Y8 -> 150000 | AB8: =D8+F8+H8+J8+L8+N8+P8+R8+T8+V8+X8+Z8 -> 30000
B9: BLU | C9: =SUMIF('手机&平板保底版销售计划数量VS 实际出货'!A:A,B9,'手机&平板保底版销售计划数量VS 实际出货'!G:G) -> 26000 | D9: =SUMIF('手机&平板保底版销售计划数量VS 实际出货'!A:A,B9,'手机&平板保底版销售计划数量VS 实际出货'!H:H) -> 25980 | E9: =SUMIF('手机&平板保底版销售计划数量VS 实际出货'!A:A,B9,'手机&平板保底版销售计划数量VS 实际出货'!I:I) -> 24000 | F9: =SUMIF('手机&平板保底版销售计划数量VS 实际出货'!A:A,B9,'手机&平板保底版销售计划数量VS 实际出货'!J:J) -> 0 | G9: =SUMIF('手机&平板保底版销售计划数量VS 实际出货'!A:A,B9,'手机&平板保底版销售计划数量VS 实际出货'!K:K) -> 0 | H9: =SUMIF('手机&平板保底版销售计划数量VS 实际出货'!A:A,B9,'手机&平板保底版销售计划数量VS 实际出货'!L:L) -> 24020 | I9: =SUMIF('手机&平板保底版销售计划数量VS 实际出货'!A:A,B9,'手机&平板保底版销售计划数量VS 实际出货'!M:M) -> 0 | J9: =SUMIF('手机&平板保底版销售计划数量VS 实际出货'!A:A,B9,'手机&平板保底版销售计划数量VS 实际出货'!N:N) -> 0 | K9: =SUMIF('手机&平板保底版销售计划数量VS 实际出货'!A:A,B9,'手机&平板保底版销售计划数量VS 实际出货'!O:O) -> 20000 | L9: =SUMIF('手机&平板保底版销售计划数量VS 实际出货'!A:A,B9,'手机&平板保底版销售计划数量VS 实际出货'!P:P) -> 41000 | M9: =SUMIF('手机&平板保底版销售计划数量VS 实际出货'!A:A,B9,'手机&平板保底版销售计划数量VS 实际出货'!Q:Q) -> 20000 | N9: =SUMIF('手机&平板保底版销售计划数量VS 实际出货'!A:A,B9,'手机&平板保底版销售计划数量VS 实际出货'!R:R) -> 30000 | O9: =SUMIF('手机&平板保底版销售计划数量VS 实际出货'!A:A,B9,'手机&平板保底版销售计划数量VS 实际出货'!S:S) -> 10000 | P9: =SUMIF('手机&平板保底版销售计划数量VS 实际出货'!A:A,B9,'手机&平板保底版销售计划数量VS 实际出货'!T:T) -> 70000 | Q9: =SUMIF('手机&平板保底版销售计划数量VS 实际出货'!A:A,B9,'手机&平板保底版销售计划数量VS 实际出货'!U:U) -> 20000 | R9: =SUMIF('手机&平板保底版销售计划数量VS 实际出货'!A:A,B9,'手机&平板保底版销售计划数量VS 实际出货'!V:V) -> 20000 | S9: =SUMIF('手机&平板保底版销售计划数量VS 实际出货'!A:A,B9,'手机&平板保底版销售计划数量VS 实际出货'!W:W) -> 10000 | T9: =SUMIF('手机&平板保底版销售计划数量VS 实际出货'!A:A,B9,'手机&平板保底版销售计划数量VS 实际出货'!X:X) -> 10000 | U9: =SUMIF('手机&平板保底版销售计划数量VS 实际出货'!A:A,B9,'手机&平板保底版销售计划数量VS 实际出货'!Y:Y) -> 10000 | V9: =SUMIF('手机&平板保底版销售计划数量VS 实际出货'!A:A,B9,'手机&平板保底版销售计划数量VS 实际出货'!Z:Z) -> 50000 | W9: =SUMIF('手机&平板保底版销售计划数量VS 实际出货'!A:A,B9,'手机&平板保底版销售计划数量VS 实际出货'!AA:AA) -> 0 | X9: =SUMIF('手机&平板保底版销售计划数量VS 实际出货'!A:A,B9,'手机&平板保底版销售计划数量VS 实际出货'!AB:AB) -> 45000 | Y9: =SUMIF('手机&平板保底版销售计划数量VS 实际出货'!A:A,B9,'手机&平板保底版销售计划数量VS 实际出货'!AC:AC) -> 10000 | Z9: =SUMIF('手机&平板保底版销售计划数量VS 实际出货'!A:A,B9,'手机&平板保底版销售计划数量VS 实际出货'!AD:AD) -> 30000 | AA9: =C9+E9+G9+I9+K9+M9+O9+Q9+S9+U9+W9+Y9 -> 150000 | AB9: =D9+F9+H9+J9+L9+N9+P9+R9+T9+V9+X9+Z9 -> 346000
B10: Doro | C10: =SUMIF('手机&平板保底版销售计划数量VS 实际出货'!A:A,B10,'手机&平板保底版销售计划数量VS 实际出货'!G:G) -> 0 | D10: =SUMIF('手机&平板保底版销售计划数量VS 实际出货'!A:A,B10,'手机&平板保底版销售计划数量VS 实际出货'!H:H) -> 5000 | E10: =SUMIF('手机&平板保底版销售计划数量VS 实际出货'!A:A,B10,'手机&平板保底版销售计划数量VS 实际出货'!I:I) -> 5000 | F10: =SUMIF('手机&平板保底版销售计划数量VS 实际出货'!A:A,B10,'手机&平板保底版销售计划数量VS 实际出货'!J:J) -> 5000 | G10: =SUMIF('手机&平板保底版销售计划数量VS 实际出货'!A:A,B10,'手机&平板保底版销售计划数量VS 实际出货'!K:K) -> 5000 | H10: =SUMIF('手机&平板保底版销售计划数量VS 实际出货'!A:A,B10,'手机&平板保底版销售计划数量VS 实际出货'!L:L) -> 0 | I10: =SUMIF('手机&平板保底版销售计划数量VS 实际出货'!A:A,B10,'手机&平板保底版销售计划数量VS 实际出货'!M:M) -> 0 | J10: =SUMIF('手机&平板保底版销售计划数量VS 实际出货'!A:A,B10,'手机&平板保底版销售计划数量VS 实际出货'!N:N) -> 0 | K10: =SUMIF('手机&平板保底版销售计划数量VS 实际出货'!A:A,B10,'手机&平板保底版销售计划数量VS 实际出货'!O:O) -> 0 | L10: =SUMIF('手机&平板保底版销售计划数量VS 实际出货'!A:A,B10,'手机&平板保底版销售计划数量VS 实际出货'!P:P) -> 0 | M10: =SUMIF('手机&平板保底版销售计划数量VS 实际出货'!A:A,B10,'手机&平板保底版销售计划数量VS 实际出货'!Q:Q) -> 0 | N10: =SUMIF('手机&平板保底版销售计划数量VS 实际出货'!A:A,B10,'手机&平板保底版销售计划数量VS 实际出货'!R:R) -> 0 | O10: =SUMIF('手机&平板保底版销售计划数量VS 实际出货'!A:A,B10,'手机&平板保底版销售计划数量VS 实际出货'!S:S) -> 0 | P10: =SUMIF('手机&平板保底版销售计划数量VS 实际出货'!A:A,B10,'手机&平板保底版销售计划数量VS 实际出货'!T:T) -> 0 | Q10: =SUMIF('手机&平板保底版销售计划数量VS 实际出货'!A:A,B10,'手机&平板保底版销售计划数量VS 实际出货'!U:U) -> 0 | R10: =SUMIF('手机&平板保底版销售计划数量VS 实际出货'!A:A,B10,'手机&平板保底版销售计划数量VS 实际出货'!V:V) -> 0 | S10: =SUMIF('手机&平板保底版销售计划数量VS 实际出货'!A:A,B10,'手机&平板保底版销售计划数量VS 实际出货'!W:W) -> 0 | T10: =SUMIF('手机&平板保底版销售计划数量VS 实际出货'!A:A,B10,'手机&平板保底版销售计划数量VS 实际出货'!X:X) -> 0 | U10: =SUMIF('手机&平板保底版销售计划数量VS 实际出货'!A:A,B10,'手机&平板保底版销售计划数量VS 实际出货'!Y:Y) -> 0 | V10: =SUMIF('手机&平板保底版销售计划数量VS 实际出货'!A:A,B10,'手机&平板保底版销售计划数量VS 实际出货'!Z:Z) -> 0 | W10: =SUMIF('手机&平板保底版销售计划数量VS 实际出货'!A:A,B10,'手机&平板保底版销售计划数量VS 实际出货'!AA:AA) -> 0 | X10: =SUMIF('手机&平板保底版销售计划数量VS 实际出货'!A:A,B10,'手机&平板保底版销售计划数量VS 实际出货'!AB:AB) -> 10000 | Y10: =SUMIF('手机&平板保底版销售计划数量VS 实际出货'!A:A,B10,'手机&平板保底版销售计划数量VS 实际出货'!AC:AC) -> 0 | Z10: =SUMIF('手机&平板保底版销售计划数量VS 实际出货'!A:A,B10,'手机&平板保底版销售计划数量VS 实际出货'!AD:AD) -> 0 | AA10: =C10+E10+G10+I10+K10+M10+O10+Q10+S10+U10+W10+Y10 -> 10000 | AB10: =D10+F10+H10+J10+L10+N10+P10+R10+T10+V10+X10+Z10 -> 20000
B11: GDL | C11: =SUMIF('手机&平板保底版销售计划数量VS 实际出货'!A:A,B11,'手机&平板保底版销售计划数量VS 实际出货'!G:G) -> 0 | D11: =SUMIF('手机&平板保底版销售计划数量VS 实际出货'!A:A,B11,'手机&平板保底版销售计划数量VS 实际出货'!H:H) -> 0 | E11: =SUMIF('手机&平板保底版销售计划数量VS 实际出货'!A:A,B11,'手机&平板保底版销售计划数量VS 实际出货'!I:I) -> 0 | F11: =SUMIF('手机&平板保底版销售计划数量VS 实际出货'!A:A,B11,'手机&平板保底版销售计划数量VS 实际出货'!J:J) -> 0 | G11: =SUMIF('手机&平板保底版销售计划数量VS 实际出货'!A:A,B11,'手机&平板保底版销售计划数量VS 实际出货'!K:K) -> 10000 | H11: =SUMIF('手机&平板保底版销售计划数量VS 实际出货'!A:A,B11,'手机&平板保底版销售计划数量VS 实际出货'!L:L) -> 0 | I11: =SUMIF('手机&平板保底版销售计划数量VS 实际出货'!A:A,B11,'手机&平板保底版销售计划数量VS 实际出货'!M:M) -> 0 | J11: =SUMIF('手机&平板保底版销售计划数量VS 实际出货'!A:A,B11,'手机&平板保底版销售计划数量VS 实际出货'!N:N) -> 10000 | K11: =SUMIF('手机&平板保底版销售计划数量VS 实际出货'!A:A,B11,'手机&平板保底版销售计划数量VS 实际出货'!O:O) -> 10000 | L11: =SUMIF('手机&平板保底版销售计划数量VS 实际出货'!A:A,B11,'手机&平板保底版销售计划数量VS 实际出货'!P:P) -> 0 | M11: =SUMIF('手机&平板保底版销售计划数量VS 实际出货'!A:A,B11,'手机&平板保底版销售计划数量VS 实际出货'!Q:Q) -> 0 | N11: =SUMIF('手机&平板保底版销售计划数量VS 实际出货'!A:A,B11,'手机&平板保底版销售计划数量VS 实际出货'!R:R) -> 10000 | O11: =SUMIF('手机&平板保底版销售计划数量VS 实际出货'!A:A,B11,'手机&平板保底版销售计划数量VS 实际出货'!S:S) -> 10000 | P11: =SUMIF('手机&平板保底版销售计划数量VS 实际出货'!A:A,B11,'手机&平板保底版销售计划数量VS 实际出货'!T:T) -> 20000 | Q11: =SUMIF('手机&平板保底版销售计划数量VS 实际出货'!A:A,B11,'手机&平板保底版销售计划数量VS 实际出货'!U:U) -> 10000 | R11: =SUMIF('手机&平板保底版销售计划数量VS 实际出货'!A:A,B11,'手机&平板保底版销售计划数量VS 实际出货'!V:V) -> 10000 | S11: =SUMIF('手机&平板保底版销售计划数量VS 实际出货'!A:A,B11,'手机&平板保底版销售计划数量VS 实际出货'!W:W) -> 10000 | T11: =SUMIF('手机&平板保底版销售计划数量VS 实际出货'!A:A,B11,'手机&平板保底版销售计划数量VS 实际出货'!X:X) -> 20000 | U11: =SUMIF('手机&平板保底版销售计划数量VS 实际出货'!A:A,B11,'手机&平板保底版销售计划数量VS 实际出货'!Y:Y) -> 10000 | V11: =SUMIF('手机&平板保底版销售计划数量VS 实际出货'!A:A,B11,'手机&平板保底版销售计划数量VS 实际出货'!Z:Z) -> 0 | W11: =SUMIF('手机&平板保底版销售计划数量VS 实际出货'!A:A,B11,'手机&平板保底版销售计划数量VS 实际出货'!AA:AA) -> 0 | X11: =SUMIF('手机&平板保底版销售计划数量VS 实际出货'!A:A,B11,'手机&平板保底版销售计划数量VS 实际出货'!AB:AB) -> 0 | Y11: =SUMIF('手机&平板保底版销售计划数量VS 实际出货'!A:A,B11,'手机&平板保底版销售计划数量VS 实际出货'!AC:AC) -> 10000 | Z11: =SUMIF('手机&平板保底版销售计划数量VS 实际出货'!A:A,B11,'手机&平板保底版销售计划数量VS 实际出货'!AD:AD) -> 0 | AA11: =C11+E11+G11+I11+K11+M11+O11+Q11+S11+U11+W11+Y11 -> 70000 | AB11: =D11+F11+H11+J11+L11+N11+P11+R11+T11+V11+X11+Z11 -> 70000
B12: Mobicel | C12: =SUMIF('手机&平板保底版销售计划数量VS 实际出货'!A:A,B12,'手机&平板保底版销售计划数量VS 实际出货'!G:G) -> 30000 | D12: =SUMIF('手机&平板保底版销售计划数量VS 实际出货'!A:A,B12,'手机&平板保底版销售计划数量VS 实际出货'!H:H) -> 30800 | E12: =SUMIF('手机&平板保底版销售计划数量VS 实际出货'!A:A,B12,'手机&平板保底版销售计划数量VS 实际出货'!I:I) -> 0 | F12: =SUMIF('手机&平板保底版销售计划数量VS 实际出货'!A:A,B12,'手机&平板保底版销售计划数量VS 实际出货'!J:J) -> 0 | G12: =SUMIF('手机&平板保底版销售计划数量VS 实际出货'!A:A,B12,'手机&平板保底版销售计划数量VS 实际出货'!K:K) -> 32500 | H12: =SUMIF('手机&平板保底版销售计划数量VS 实际出货'!A:A,B12,'手机&平板保底版销售计划数量VS 实际出货'!L:L) -> 32500 | I12: =SUMIF('手机&平板保底版销售计划数量VS 实际出货'!A:A,B12,'手机&平板保底版销售计划数量VS 实际出货'!M:M) -> 0 | J12: =SUMIF('手机&平板保底版销售计划数量VS 实际出货'!A:A,B12,'手机&平板保底版销售计划数量VS 实际出货'!N:N) -> 20000 | K12: =SUMIF('手机&平板保底版销售计划数量VS 实际出货'!A:A,B12,'手机&平板保底版销售计划数量VS 实际出货'!O:O) -> 40000 | L12: =SUMIF('手机&平板保底版销售计划数量VS 实际出货'!A:A,B12,'手机&平板保底版销售计划数量VS 实际出货'!P:P) -> 15000 | M12: =SUMIF('手机&平板保底版销售计划数量VS 实际出货'!A:A,B12,'手机&平板保底版销售计划数量VS 实际出货'!Q:Q) -> 0 | N12: =SUMIF('手机&平板保底版销售计划数量VS 实际出货'!A:A,B12,'手机&平板保底版销售计划数量VS 实际出货'!R:R) -> 35000 | O12: =SUMIF('手机&平板保底版销售计划数量VS 实际出货'!A:A,B12,'手机&平板保底版销售计划数量VS 实际出货'!S:S) -> 40000 | P12: =SUMIF('手机&平板保底版销售计划数量VS 实际出货'!A:A,B12,'手机&平板保底版销售计划数量VS 实际出货'!T:T) -> 0 | Q12: =SUMIF('手机&平板保底版销售计划数量VS 实际出货'!A:A,B12,'手机&平板保底版销售计划数量VS 实际出货'!U:U) -> 0 | R12: =SUMIF('手机&平板保底版销售计划数量VS 实际出货'!A:A,B12,'手机&平板保底版销售计划数量VS 实际出货'!V:V) -> 0 | S12: =SUMIF('手机&平板保底版销售计划数量VS 实际出货'!A:A,B12,'手机&平板保底版销售计划数量VS 实际出货'!W:W) -> 10000 | T12: =SUMIF('手机&平板保底版销售计划数量VS 实际出货'!A:A,B12,'手机&平板保底版销售计划数量VS 实际出货'!X:X) -> 0 | U12: =SUMIF('手机&平板保底版销售计划数量VS 实际出货'!A:A,B12,'手机&平板保底版销售计划数量VS 实际出货'!Y:Y) -> 0 | V12: =SUMIF('手机&平板保底版销售计划数量VS 实际出货'!A:A,B12,'手机&平板保底版销售计划数量VS 实际出货'!Z:Z) -> 0 | W12: =SUMIF('手机&平板保底版销售计划数量VS 实际出货'!A:A,B12,'手机&平板保底版销售计划数量VS 实际出货'!AA:AA) -> 0 | X12: =SUMIF('手机&平板保底版销售计划数量VS 实际出货'!A:A,B12,'手机&平板保底版销售计划数量VS 实际出货'!AB:AB) -> 0 | Y12: =SUMIF('手机&平板保底版销售计划数量VS 实际出货'!A:A,B12,'手机&平板保底版销售计划数量VS 实际出货'!AC:AC) -> 0 | Z12: =SUMIF('手机&平板保底版销售计划数量VS 实际出货'!A:A,B12,'手机&平板保底版销售计划数量VS 实际出货'!AD:AD) -> 0 | AA12: =C12+E12+G12+I12+K12+M12+O12+Q12+S12+U12+W12+Y12 -> 152500 | AB12: =D12+F12+H12+J12+L12+N12+P12+R12+T12+V12+X12+Z12 -> 133300
B13: AI | C13: =SUMIF('手机&平板保底版销售计划数量VS 实际出货'!A:A,B13,'手机&平板保底版销售计划数量VS 实际出货'!G:G) -> 0 | D13: =SUMIF('手机&平板保底版销售计划数量VS 实际出货'!A:A,B13,'手机&平板保底版销售计划数量VS 实际出货'!H:H) -> 0 | E13: =SUMIF('手机&平板保底版销售计划数量VS 实际出货'!A:A,B13,'手机&平板保底版销售计划数量VS 实际出货'!I:I) -> 0 | F13: =SUMIF('手机&平板保底版销售计划数量VS 实际出货'!A:A,B13,'手机&平板保底版销售计划数量VS 实际出货'!J:J) -> 0 | G13: =SUMIF('手机&平板保底版销售计划数量VS 实际出货'!A:A,B13,'手机&平板保底版销售计划数量VS 实际出货'!K:K) -> 0 | H13: =SUMIF('手机&平板保底版销售计划数量VS 实际出货'!A:A,B13,'手机&平板保底版销售计划数量VS 实际出货'!L:L) -> 0 | I13: =SUMIF('手机&平板保底版销售计划数量VS 实际出货'!A:A,B13,'手机&平板保底版销售计划数量VS 实际出货'!M:M) -> 0 | J13: =SUMIF('手机&平板保底版销售计划数量VS 实际出货'!A:A,B13,'手机&平板保底版销售计划数量VS 实际出货'!N:N) -> 0 | K13: =SUMIF('手机&平板保底版销售计划数量VS 实际出货'!A:A,B13,'手机&平板保底版销售计划数量VS 实际出货'!O:O) -> 0 | L13: =SUMIF('手机&平板保底版销售计划数量VS 实际出货'!A:A,B13,'手机&平板保底版销售计划数量VS 实际出货'!P:P) -> 500 | M13: =SUMIF('手机&平板保底版销售计划数量VS 实际出货'!A:A,B13,'手机&平板保底版销售计划数量VS 实际出货'!Q:Q) -> 0 | N13: =SUMIF('手机&平板保底版销售计划数量VS 实际出货'!A:A,B13,'手机&平板保底版销售计划数量VS 实际出货'!R:R) -> 80000 | O13: =SUMIF('手机&平板保底版销售计划数量VS 实际出货'!A:A,B13,'手机&平板保底版销售计划数量VS 实际出货'!S:S) -> 0 | P13: =SUMIF('手机&平板保底版销售计划数量VS 实际出货'!A:A,B13,'手机&平板保底版销售计划数量VS 实际出货'!T:T) -> 179500 | Q13: =SUMIF('手机&平板保底版销售计划数量VS 实际出货'!A:A,B13,'手机&平板保底版销售计划数量VS 实际出货'!U:U) -> 0 | R13: =SUMIF('手机&平板保底版销售计划数量VS 实际出货'!A:A,B13,'手机&平板保底版销售计划数量VS 实际出货'!V:V) -> 90000 | S13: =SUMIF('手机&平板保底版销售计划数量VS 实际出货'!A:A,B13,'手机&平板保底版销售计划数量VS 实际出货'!W:W) -> 0 | T13: =SUMIF('手机&平板保底版销售计划数量VS 实际出货'!A:A,B13,'手机&平板保底版销售计划数量VS 实际出货'!X:X) -> 260000 | U13: =SUMIF('手机&平板保底版销售计划数量VS 实际出货'!A:A,B13,'手机&平板保底版销售计划数量VS 实际出货'!Y:Y) -> 0 | V13: =SUMIF('手机&平板保底版销售计划数量VS 实际出货'!A:A,B13,'手机&平板保底版销售计划数量VS 实际出货'!Z:Z) -> 90000 | W13: =SUMIF('手机&平板保底版销售计划数量VS 实际出货'!A:A,B13,'手机&平板保底版销售计划数量VS 实际出货'!AA:AA) -> 0 | X13: =SUMIF('手机&平板保底版销售计划数量VS 实际出货'!A:A,B13,'手机&平板保底版销售计划数量VS 实际出货'!AB:AB) -> 0 | Y13: =SUMIF('手机&平板保底版销售计划数量VS 实际出货'!A:A,B13,'手机&平板保底版销售计划数量VS 实际出货'!AC:AC) -> 0 | Z13: =SUMIF('手机&平板保底版销售计划数量VS 实际出货'!A:A,B13,'手机&平板保底版销售计划数量VS 实际出货'!AD:AD) -> 20000 | AA13: =C13+E13+G13+I13+K13+M13+O13+Q13+S13+U13+W13+Y13 -> 0 | AB13: =D13+F13+H13+J13+L13+N13+P13+R13+T13+V13+X13+Z13 -> 720000
B14: GV | C14: =SUMIF('手机&平板保底版销售计划数量VS 实际出货'!A:A,B14,'手机&平板保底版销售计划数量VS 实际出货'!G:G) -> 0 | D14: =SUMIF('手机&平板保底版销售计划数量VS 实际出货'!A:A,B14,'手机&平板保底版销售计划数量VS 实际出货'!H:H) -> 0 | E14: =SUMIF('手机&平板保底版销售计划数量VS 实际出货'!A:A,B14,'手机&平板保底版销售计划数量VS 实际出货'!I:I) -> 0 | F14: =SUMIF('手机&平板保底版销售计划数量VS 实际出货'!A:A,B14,'手机&平板保底版销售计划数量VS 实际出货'!J:J) -> 0 | G14: =SUMIF('手机&平板保底版销售计划数量VS 实际出货'!A:A,B14,'手机&平板保底版销售计划数量VS 实际出货'!K:K) -> 0 | H14: =SUMIF('手机&平板保底版销售计划数量VS 实际出货'!A:A,B14,'手机&平板保底版销售计划数量VS 实际出货'!L:L) -> 0 | I14: =SUMIF('手机&平板保底版销售计划数量VS 实际出货'!A:A,B14,'手机&平板保底版销售计划数量VS 实际出货'!M:M) -> 0 | J14: =SUMIF('手机&平板保底版销售计划数量VS 实际出货'!A:A,B14,'手机&平板保底版销售计划数量VS 实际出货'!N:N) -> 0 | K14: =SUMIF('手机&平板保底版销售计划数量VS 实际出货'!A:A,B14,'手机&平板保底版销售计划数量VS 实际出货'!O:O) -> 0 | L14: =SUMIF('手机&平板保底版销售计划数量VS 实际出货'!A:A,B14,'手机&平板保底版销售计划数量VS 实际出货'!P:P) -> 10000 | M14: =SUMIF('手机&平板保底版销售计划数量VS 实际出货'!A:A,B14,'手机&平板保底版销售计划数量VS 实际出货'!Q:Q) -> 0 | N14: =SUMIF('手机&平板保底版销售计划数量VS 实际出货'!A:A,B14,'手机&平板保底版销售计划数量VS 实际出货'!R:R) -> 0 | O14: =SUMIF('手机&平板保底版销售计划数量VS 实际出货'!A:A,B14,'手机&平板保底版销售计划数量VS 实际出货'!S:S) -> 0 | P14: =SUMIF('手机&平板保底版销售计划数量VS 实际出货'!A:A,B14,'手机&平板保底版销售计划数量VS 实际出货'!T:T) -> 10000 | Q14: =SUMIF('手机&平板保底版销售计划数量VS 实际出货'!A:A,B14,'手机&平板保底版销售计划数量VS 实际出货'!U:U) -> 0 | R14: =SUMIF('手机&平板保底版销售计划数量VS 实际出货'!A:A,B14,'手机&平板保底版销售计划数量VS 实际出货'!V:V) -> 0 | S14: =SUMIF('手机&平板保底版销售计划数量VS 实际出货'!A:A,B14,'手机&平板保底版销售计划数量VS 实际出货'!W:W) -> 0 | T14: =SUMIF('手机&平板保底版销售计划数量VS 实际出货'!A:A,B14,'手机&平板保底版销售计划数量VS 实际出货'!X:X) -> 10000 | U14: =SUMIF('手机&平板保底版销售计划数量VS 实际出货'!A:A,B14,'手机&平板保底版销售计划数量VS 实际出货'!Y:Y) -> 0 | V14: =SUMIF('手机&平板保底版销售计划数量VS 实际出货'!A:A,B14,'手机&平板保底版销售计划数量VS 实际出货'!Z:Z) -> 0 | W14: =SUMIF('手机&平板保底版销售计划数量VS 实际出货'!A:A,B14,'手机&平板保底版销售计划数量VS 实际出货'!AA:AA) -> 0 | X14: =SUMIF('手机&平板保底版销售计划数量VS 实际出货'!A:A,B14,'手机&平板保底版销售计划数量VS 实际出货'!AB:AB) -> 10000 | Y14: =SUMIF('手机&平板保底版销售计划数量VS 实际出货'!A:A,B14,'手机&平板保底版销售计划数量VS 实际出货'!AC:AC) -> 0 | Z14: =SUMIF('手机&平板保底版销售计划数量VS 实际出货'!A:A,B14,'手机&平板保底版销售计划数量VS 实际出货'!AD:AD) -> 30000 | AA14: =C14+E14+G14+I14+K14+M14+O14+Q14+S14+U14+W14+Y14 -> 0 | AB14: =D14+F14+H14+J14+L14+N14+P14+R14+T14+V14+X14+Z14 -> 70000
B15: LT | C15: =SUMIF('手机&平板保底版销售计划数量VS 实际出货'!A:A,B15,'手机&平板保底版销售计划数量VS 实际出货'!G:G) -> 0 | D15: =SUMIF('手机&平板保底版销售计划数量VS 实际出货'!A:A,B15,'手机&平板保底版销售计划数量VS 实际出货'!H:H) -> 0 | E15: =SUMIF('手机&平板保底版销售计划数量VS 实际出货'!A:A,B15,'手机&平板保底版销售计划数量VS 实际出货'!I:I) -> 0 | F15: =SUMIF('手机&平板保底版销售计划数量VS 实际出货'!A:A,B15,'手机&平板保底版销售计划数量VS 实际出货'!J:J) -> 0 | G15: =SUMIF('手机&平板保底版销售计划数量VS 实际出货'!A:A,B15,'手机&平板保底版销售计划数量VS 实际出货'!K:K) -> 0 | H15: =SUMIF('手机&平板保底版销售计划数量VS 实际出货'!A:A,B15,'手机&平板保底版销售计划数量VS 实际出货'!L:L) -> 0 | I15: =SUMIF('手机&平板保底版销售计划数量VS 实际出货'!A:A,B15,'手机&平板保底版销售计划数量VS 实际出货'!M:M) -> 20000 | J15: =SUMIF('手机&平板保底版销售计划数量VS 实际出货'!A:A,B15,'手机&平板保底版销售计划数量VS 实际出货'!N:N) -> 0 | K15: =SUMIF('手机&平板保底版销售计划数量VS 实际出货'!A:A,B15,'手机&平板保底版销售计划数量VS 实际出货'!O:O) -> 0 | L15: =SUMIF('手机&平板保底版销售计划数量VS 实际出货'!A:A,B15,'手机&平板保底版销售计划数量VS 实际出货'!P:P) -> 0 | M15: =SUMIF('手机&平板保底版销售计划数量VS 实际出货'!A:A,B15,'手机&平板保底版销售计划数量VS 实际出货'!Q:Q) -> 0 | N15: =SUMIF('手机&平板保底版销售计划数量VS 实际出货'!A:A,B15,'手机&平板保底版销售计划数量VS 实际出货'!R:R) -> 0 | O15: =SUMIF('手机&平板保底版销售计划数量VS 实际出货'!A:A,B15,'手机&平板保底版销售计划数量VS 实际出货'!S:S) -> 10000 | P15: =SUMIF('手机&平板保底版销售计划数量VS 实际出货'!A:A,B15,'手机&平板保底版销售计划数量VS 实际出货'!T:T) -> 0 | Q15: =SUMIF('手机&平板保底版销售计划数量VS 实际出货'!A:A,B15,'手机&平板保底版销售计划数量VS 实际出货'!U:U) -> 0 | R15: =SUMIF('手机&平板保底版销售计划数量VS 实际出货'!A:A,B15,'手机&平板保底版销售计划数量VS 实际出货'!V:V) -> 0 | S15: =SUMIF('手机&平板保底版销售计划数量VS 实际出货'!A:A,B15,'手机&平板保底版销售计划数量VS 实际出货'!W:W) -> 10000 | T15: =SUMIF('手机&平板保底版销售计划数量VS 实际出货'!A:A,B15,'手机&平板保底版销售计划数量VS 实际出货'!X:X) -> 0 | U15: =SUMIF('手机&平板保底版销售计划数量VS 实际出货'!A:A,B15,'手机&平板保底版销售计划数量VS 实际出货'!Y:Y) -> 0 | V15: =SUMIF('手机&平板保底版销售计划数量VS 实际出货'!A:A,B15,'手机&平板保底版销售计划数量VS 实际出货'!Z:Z) -> 0 | W15: =SUMIF('手机&平板保底版销售计划数量VS 实际出货'!A:A,B15,'手机&平板保底版销售计划数量VS 实际出货'!AA:AA) -> 0 | X15: =SUMIF('手机&平板保底版销售计划数量VS 实际出货'!A:A,B15,'手机&平板保底版销售计划数量VS 实际出货'!AB:AB) -> 0 | Y15: =SUMIF('手机&平板保底版销售计划数量VS 实际出货'!A:A,B15,'手机&平板保底版销售计划数量VS 实际出货'!AC:AC) -> 0 | Z15: =SUMIF('手机&平板保底版销售计划数量VS 实际出货'!A:A,B15,'手机&平板保底版销售计划数量VS 实际出货'!AD:AD) -> 0 | AA15: =C15+E15+G15+I15+K15+M15+O15+Q15+S15+U15+W15+Y15 -> 40000 | AB15: =D15+F15+H15+J15+L15+N15+P15+R15+T15+V15+X15+Z15 -> 0
... B29: TAL | C29: =SUMIF('手机&平板保底版销售计划数量VS 实际出货'!A:A,B29,'手机&平板保底版销售计划数量VS 实际出货'!G:G) -> 716 | D29: =SUMIF('手机&平板保底版销售计划数量VS 实际出货'!A:A,B29,'手机&平板保底版销售计划数量VS 实际出货'!H:H) -> 716 | E29: =SUMIF('手机&平板保底版销售计划数量VS 实际出货'!A:A,B29,'手机&平板保底版销售计划数量VS 实际出货'!I:I) -> 904 | F29: =SUMIF('手机&平板保底版销售计划数量VS 实际出货'!A:A,B29,'手机&平板保底版销售计划数量VS 实际出货'!J:J) -> 10800 | G29: =SUMIF('手机&平板保底版销售计划数量VS 实际出货'!A:A,B29,'手机&平板保底版销售计划数量VS 实际出货'!K:K) -> 31380 | H29: =SUMIF('手机&平板保底版销售计划数量VS 实际出货'!A:A,B29,'手机&平板保底版销售计划数量VS 实际出货'!L:L) -> 21484 | I29: =SUMIF('手机&平板保底版销售计划数量VS 实际出货'!A:A,B29,'手机&平板保底版销售计划数量VS 实际出货'!M:M) -> 0 | J29: =SUMIF('手机&平板保底版销售计划数量VS 实际出货'!A:A,B29,'手机&平板保底版销售计划数量VS 实际出货'!N:N) -> 0 | K29: =SUMIF('手机&平板保底版销售计划数量VS 实际出货'!A:A,B29,'手机&平板保底版销售计划数量VS 实际出货'!O:O) -> 5000 | L29: =SUMIF('手机&平板保底版销售计划数量VS 实际出货'!A:A,B29,'手机&平板保底版销售计划数量VS 实际出货'!P:P) -> 2084 | M29: =SUMIF('手机&平板保底版销售计划数量VS 实际出货'!A:A,B29,'手机&平板保底版销售计划数量VS 实际出货'!Q:Q) -> 0 | N29: =SUMIF('手机&平板保底版销售计划数量VS 实际出货'!A:A,B29,'手机&平板保底版销售计划数量VS 实际出货'!R:R) -> 0 | O29: =SUMIF('手机&平板保底版销售计划数量VS 实际出货'!A:A,B29,'手机&平板保底版销售计划数量VS 实际出货'!S:S) -> 0 | P29: =SUMIF('手机&平板保底版销售计划数量VS 实际出货'!A:A,B29,'手机&平板保底版销售计划数量VS 实际出货'!T:T) -> 0 | Q29: =SUMIF('手机&平板保底版销售计划数量VS 实际出货'!A:A,B29,'手机&平板保底版销售计划数量VS 实际出货'!U:U) -> 0 | R29: =SUMIF('手机&平板保底版销售计划数量VS 实际出货'!A:A,B29,'手机&平板保底版销售计划数量VS 实际出货'!V:V) -> 0 | S29: =SUMIF('手机&平板保底版销售计划数量VS 实际出货'!A:A,B29,'手机&平板保底版销售计划数量VS 实际出货'!W:W) -> 0 | T29: =SUMIF('手机&平板保底版销售计划数量VS 实际出货'!A:A,B29,'手机&平板保底版销售计划数量VS 实际出货'!X:X) -> 2916 | U29: =SUMIF('手机&平板保底版销售计划数量VS 实际出货'!A:A,B29,'手机&平板保底版销售计划数量VS 实际出货'!Y:Y) -> 0 | V29: =SUMIF('手机&平板保底版销售计划数量VS 实际出货'!A:A,B29,'手机&平板保底版销售计划数量VS 实际出货'!Z:Z) -> 0 | W29: =SUMIF('手机&平板保底版销售计划数量VS 实际出货'!A:A,B29,'手机&平板保底版销售计划数量VS 实际出货'!AA:AA) -> 0 | X29: =SUMIF('手机&平板保底版销售计划数量VS 实际出货'!A:A,B29,'手机&平板保底版销售计划数量VS 实际出货'!AB:AB) -> 0 | Y29: =SUMIF('手机&平板保底版销售计划数量VS 实际出货'!A:A,B29,'手机&平板保底版销售计划数量VS 实际出货'!AC:AC) -> 0 | Z29: =SUMIF('手机&平板保底版销售计划数量VS 实际出货'!A:A,B29,'手机&平板保底版销售计划数量VS 实际出货'!AD:AD) -> 0 | AA29: =C29+E29+G29+I29+K29+M29+O29+Q29+S29+U29+W29+Y29 -> 38000 | AB29: =D29+F29+H29+J29+L29+N29+P29+R29+T29+V29+X29+Z29 -> 38000
B30: 汇总 | C30: =SUM(C4:C29) -> 2129871 | D30: =SUM(D4:D29) -> 2253215 | E30: =SUM(E4:E29) -> 1774948 | F30: =SUM(F4:F29) -> 1369112 | G30: =SUM(G4:G29) -> 1973093 | H30: =SUM(H4:H29) -> 1551175 | I30: =SUM(I4:I29) -> 1663731 | J30: =SUM(J4:J29) -> 1314512 | ... AB30: =SUM(AB4:AB29) -> 23958863
B32: 功能机与智能机分布： | AF32: CBU,SKD与CKD分布：
B33: Type | C33: 1月分解 | D33: 1月实际 | E33: 2月分解 | F33: 2月实际 | G33: 3月分解 | H33: 3月实际 | I33: 4月分解 | J33: 4月实际 | K33: 5月分解 | L33: 5月实际 | M33: 6月分解 | N33: 6月实际 | O33: 7月分解 | P33: 7月实际 | Q33: 8月分解 | R33: 8月实际 | S33: 9月分解 | T33: 9月实际 | U33: 10月分解 | V33: 10月实际 | W33: 11月分解 | X33: 11月实际 | Y33: 12月分解 | Z33: 12月实际 | AA33: 全年分解 | AB33: 全年实际 | AF33: Type | AG33: 1月 | AH33: 2月 | AI33: 3月 | AJ33: 4月 | AK33: 5月 | AL33: 6月 | AM33: 7月 | AN33: 8月 | AO33: 9月 | AP33: 10月 | AQ33: 11月 | AR33: 12月 | AS33: 全年
B34: FP | C34: =SUMIF('手机&平板保底版销售计划数量VS 实际出货'!E:E,B34,'手机&平板保底版销售计划数量VS 实际出货'!G:G) -> 1460000 | D34: =SUMIF('手机&平板保底版销售计划数量VS 实际出货'!E:E,B34,'手机&平板保底版销售计划数量VS 实际出货'!H:H) -> 1613262 | E34: =SUMIF('手机&平板保底版销售计划数量VS 实际出货'!E:E,B34,'手机&平板保底版销售计划数量VS 实际出货'!I:I) -> 1355000 | F34: =SUMIF('手机&平板保底版销售计划数量VS 实际出货'!E:E,B34,'手机&平板保底版销售计划数量VS 实际出货'!J:J) -> 930376 | G34: =SUMIF('手机&平板保底版销售计划数量VS 实际出货'!E:E,B34,'手机&平板保底版销售计划数量VS 实际出货'!K:K) -> 1255000 | H34: =SUMIF('手机&平板保底版销售计划数量VS 实际出货'!E:E,B34,'手机&平板保底版销售计划数量VS 实际出货'!L:L) -> 943772 | I34: =SUMIF('手机&平板保底版销售计划数量VS 实际出货'!E:E,B34,'手机&平板保底版销售计划数量VS 实际出货'!M:M) -> 1250000 | J34: =SUMIF('手机&平板保底版销售计划数量VS 实际出货'!E:E,B34,'手机&平板保底版销售计划数量VS 实际出货'!N:N) -> 821378 | K34: =SUMIF('手机&平板保底版销售计划数量VS 实际出货'!E:E,B34,'手机&平板保底版销售计划数量VS 实际出货'!O:O) -> 1320000 | L34: =SUMIF('手机&平板保底版销售计划数量VS 实际出货'!E:E,B34,'手机&平板保底版销售计划数量VS 实际出货'!P:P) -> 1095490 | M34: =SUMIF('手机&平板保底版销售计划数量VS 实际出货'!E:E,B34,'手机&平板保底版销售计划数量VS 实际出货'!Q:Q) -> 1350000 | N34: =SUMIF('手机&平板保底版销售计划数量VS 实际出货'!E:E,B34,'手机&平板保底版销售计划数量VS 实际出货'!R:R) -> 724562 | O34: =SUMIF('手机&平板保底版销售计划数量VS 实际出货'!E:E,B34,'手机&平板保底版销售计划数量VS 实际出货'!S:S) -> 1640000 | P34: =SUMIF('手机&平板保底版销售计划数量VS 实际出货'!E:E,B34,'手机&平板保底版销售计划数量VS 实际出货'!T:T) -> 851544 | Q34: =SUMIF('手机&平板保底版销售计划数量VS 实际出货'!E:E,B34,'手机&平板保底版销售计划数量VS 实际出货'!U:U) -> 1560000 | R34: =SUMIF('手机&平板保底版销售计划数量VS 实际出货'!E:E,B34,'手机&平板保底版销售计划数量VS 实际出货'!V:V) -> 769702 | S34: =SUMIF('手机&平板保底版销售计划数量VS 实际出货'!E:E,B34,'手机&平板保底版销售计划数量VS 实际出货'!W:W) -> 1660000 | T34: =SUMIF('手机&平板保底版销售计划数量VS 实际出货'!E:E,B34,'手机&平板保底版销售计划数量VS 实际出货'!X:X) -> 1137450 | U34: =SUMIF('手机&平板保底版销售计划数量VS 实际出货'!E:E,B34,'手机&平板保底版销售计划数量VS 实际出货'!Y:Y) -> 1710000 | V34: =SUMIF('手机&平板保底版销售计划数量VS 实际出货'!E:E,B34,'手机&平板保底版销售计划数量VS 实际出货'!Z:Z) -> 1219616 | W34: =SUMIF('手机&平板保底版销售计划数量VS 实际出货'!E:E,B34,'手机&平板保底版销售计划数量VS 实际出货'!AA:AA) -> 946000 | X34: =SUMIF('手机&平板保底版销售计划数量VS 实际出货'!E:E,B34,'手机&平板保底版销售计划数量VS 实际出货'!AB:AB) -> 1481084 | Y34: =SUMIF('手机&平板保底版销售计划数量VS 实际出货'!E:E,B34,'手机&平板保底版销售计划数量VS 实际出货'!AC:AC) -> 903000 | Z34: =SUMIF('手机&平板保底版销售计划数量VS 实际出货'!E:E,B34,'手机&平板保底版销售计划数量VS 实际出货'!AD:AD) -> 1498019 | AA34: =C34+E34+G34+I34+K34+M34+O34+Q34+S34+U34+W34+Y34 -> 16409000 | AB34: =D34+F34+H34+J34+L34+N34+P34+R34+T34+V34+X34+Z34 -> 13086255 | AF34: CBU/FP | AG34: =SUMIFS('手机&平板保底版销售计划数量VS 实际出货'!G:G,'手机&平板保底版销售计划数量VS 实际出货'!D:D,"CBU",'手机&平板保底版销售计划数量VS 实际出货'!E:E,"FP") -> 0 | AH34: =SUMIFS('手机&平板保底版销售计划数量VS 实际出货'!I:I,'手机&平板保底版销售计划数量VS 实际出货'!D:D,"CBU",'手机&平板保底版销售计划数量VS 实际出货'!E:E,"FP") -> 5000 | AI34: =SUMIFS('手机&平板保底版销售计划数量VS 实际出货'!K:K,'手机&平板保底版销售计划数量VS 实际出货'!D:D,"CBU",'手机&平板保底版销售计划数量VS 实际出货'!E:E,"FP") -> 5000 | AJ34: =SUMIFS('手机&平板保底版销售计划数量VS 实际出货'!M:M,'手机&平板保底版销售计划数量VS 实际出货'!D:D,"CBU",'手机&平板保底版销售计划数量VS 实际出货'!E:E,"FP") -> 0 | AK34: =SUMIFS('手机&平板保底版销售计划数量VS 实际出货'!O:O,'手机&平板保底版销售计划数量VS 实际出货'!D:D,"CBU",'手机&平板保底版销售计划数量VS 实际出货'!E:E,"FP") -> 0 | AL34: =SUMIFS('手机&平板保底版销售计划数量VS 实际出货'!Q:Q,'手机&平板保底版销售计划数量VS 实际出货'!D:D,"CBU",'手机&平板保底版销售计划数量VS 实际出货'!E:E,"FP") -> 0 | AM34: =SUMIFS('手机&平板保底版销售计划数量VS 实际出货'!S:S,'手机&平板保底版销售计划数量VS 实际出货'!D:D,"CBU",'手机&平板保底版销售计划数量VS 实际出货'!E:E,"FP") -> 0 | AN34: =SUMIFS('手机&平板保底版销售计划数量VS 实际出货'!U:U,'手机&平板保底版销售计划数量VS 实际出货'!D:D,"CBU",'手机&平板保底版销售计划数量VS 实际出货'!E:E,"FP") -> 0 | AO34: =SUMIFS('手机&平板保底版销售计划数量VS 实际出货'!W:W,'手机&平板保底版销售计划数量VS 实际出货'!D:D,"CBU",'手机&平板保底版销售计划数量VS 实际出货'!E:E,"FP") -> 0 | AP34: =SUMIFS('手机&平板保底版销售计划数量VS 实际出货'!Y:Y,'手机&平板保底版销售计划数量VS 实际出货'!D:D,"CBU",'手机&平板保底版销售计划数量VS 实际出货'!E:E,"FP") -> 0 | AQ34: =SUMIFS('手机&平板保底版销售计划数量VS 实际出货'!AA:AA,'手机&平板保底版销售计划数量VS 实际出货'!D:D,"CBU",'手机&平板保底版销售计划数量VS 实际出货'!E:E,"FP") -> 0 | AR34: =SUMIFS('手机&平板保底版销售计划数量VS 实际出货'!AC:AC,'手机&平板保底版销售计划数量VS 实际出货'!D:D,"CBU",'手机&平板保底版销售计划数量VS 实际出货'!E:E,"FP") -> 0 | AS34: =SUM(AG34:AR34) -> 10000
B35: PAD | C35: =SUMIF('手机&平板保底版销售计划数量VS 实际出货'!E:E,B35,'手机&平板保底版销售计划数量VS 实际出货'!G:G) -> 93988 | D35: =SUMIF('手机&平板保底版销售计划数量VS 实际出货'!E:E,B35,'手机&平板保底版销售计划数量VS 实际出货'!H:H) -> 97896 | E35: =SUMIF('手机&平板保底版销售计划数量VS 实际出货'!E:E,B35,'手机&平板保底版销售计划数量VS 实际出货'!I:I) -> 88904 | F35: =SUMIF('手机&平板保底版销售计划数量VS 实际出货'!E:E,B35,'手机&平板保底版销售计划数量VS 实际出货'!J:J) -> 100660 | G35: =SUMIF('手机&平板保底版销售计划数量VS 实际出货'!E:E,B35,'手机&平板保底版销售计划数量VS 实际出货'!K:K) -> 117380 | H35: =SUMIF('手机&平板保底版销售计划数量VS 实际出货'!E:E,B35,'手机&平板保底版销售计划数量VS 实际出货'!L:L) -> 101294 | I35: =SUMIF('手机&平板保底版销售计划数量VS 实际出货'!E:E,B35,'手机&平板保底版销售计划数量VS 实际出货'!M:M) -> 70473 | J35: =SUMIF('手机&平板保底版销售计划数量VS 实际出货'!E:E,B35,'手机&平板保底版销售计划数量VS 实际出货'!N:N) -> 62952 | K35: =SUMIF('手机&平板保底版销售计划数量VS 实际出货'!E:E,B35,'手机&平板保底版销售计划数量VS 实际出货'!O:O) -> 90000 | L35: =SUMIF('手机&平板保底版销售计划数量VS 实际出货'!E:E,B35,'手机&平板保底版销售计划数量VS 实际出货'!P:P) -> 92918 | M35: =SUMIF('手机&平板保底版销售计划数量VS 实际出货'!E:E,B35,'手机&平板保底版销售计划数量VS 实际出货'!Q:Q) -> 85000 | N35: =SUMIF('手机&平板保底版销售计划数量VS 实际出货'!E:E,B35,'手机&平板保底版销售计划数量VS 实际出货'!R:R) -> 112620 | O35: =SUMIF('手机&平板保底版销售计划数量VS 实际出货'!E:E,B35,'手机&平板保底版销售计划数量VS 实际出货'!S:S) -> 75000 | P35: =SUMIF('手机&平板保底版销售计划数量VS 实际出货'!E:E,B35,'手机&平板保底版销售计划数量VS 实际出货'!T:T) -> 178550 | Q35: =SUMIF('手机&平板保底版销售计划数量VS 实际出货'!E:E,B35,'手机&平板保底版销售计划数量VS 实际出货'!U:U) -> 79000 | R35: =SUMIF('手机&平板保底版销售计划数量VS 实际出货'!E:E,B35,'手机&平板保底版销售计划数量VS 实际出货'!V:V) -> 321840 | S35: =SUMIF('手机&平板保底版销售计划数量VS 实际出货'!E:E,B35,'手机&平板保底版销售计划数量VS 实际出货'!W:W) -> 70000 | T35: =SUMIF('手机&平板保底版销售计划数量VS 实际出货'!E:E,B35,'手机&平板保底版销售计划数量VS 实际出货'!X:X) -> 300266 | U35: =SUMIF('手机&平板保底版销售计划数量VS 实际出货'!E:E,B35,'手机&平板保底版销售计划数量VS 实际出货'!Y:Y) -> 71000 | V35: =SUMIF('手机&平板保底版销售计划数量VS 实际出货'!E:E,B35,'手机&平板保底版销售计划数量VS 实际出货'!Z:Z) -> 121740 | W35: =SUMIF('手机&平板保底版销售计划数量VS 实际出货'!E:E,B35,'手机&平板保底版销售计划数量VS 实际出货'!AA:AA) -> 87965 | X35: =SUMIF('手机&平板保底版销售计划数量VS 实际出货'!E:E,B35,'手机&平板保底版销售计划数量VS 实际出货'!AB:AB) -> 94594 | Y35: =SUMIF('手机&平板保底版销售计划数量VS 实际出货'!E:E,B35,'手机&平板保底版销售计划数量VS 实际出货'!AC:AC) -> 70000 | Z35: =SUMIF('手机&平板保底版销售计划数量VS 实际出货'!E:E,B35,'手机&平板保底版销售计划数量VS 实际出货'!AD:AD) -> 40204 | AA35: =C35+E35+G35+I35+K35+M35+O35+Q35+S35+U35+W35+Y35 -> 998710 | AB35: =D35+F35+H35+J35+L35+N35+P35+R35+T35+V35+X35+Z35 -> 1625534 | AF35: CBU/FP | AG35: =SUMIFS('手机&平板保底版销售计划数量VS 实际出货'!G:G,'手机&平板保底版销售计划数量VS 实际出货'!D:D,"CBU",'手机&平板保底版销售计划数量VS 实际出货'!E:E,"FP") -> 0 | AH35: =SUMIFS('手机&平板保底版销售计划数量VS 实际出货'!I:I,'手机&平板保底版销售计划数量VS 实际出货'!D:D,"CBU",'手机&平板保底版销售计划数量VS 实际出货'!E:E,"FP") -> 5000 | AI35: =SUMIFS('手机&平板保底版销售计划数量VS 实际出货'!K:K,'手机&平板保底版销售计划数量VS 实际出货'!D:D,"CBU",'手机&平板保底版销售计划数量VS 实际出货'!E:E,"FP") -> 5000 | AJ35: =SUMIFS('手机&平板保底版销售计划数量VS 实际出货'!M:M,'手机&平板保底版销售计划数量VS 实际出货'!D:D,"CBU",'手机&平板保底版销售计划数量VS 实际出货'!E:E,"FP") -> 0 | AK35: =SUMIFS('手机&平板保底版销售计划数量VS 实际出货'!O:O,'手机&平板保底版销售计划数量VS 实际出货'!D:D,"CBU",'手机&平板保底版销售计划数量VS 实际出货'!E:E,"FP") -> 0 | AL35: =SUMIFS('手机&平板保底版销售计划数量VS 实际出货'!Q:Q,'手机&平板保底版销售计划数量VS 实际出货'!D:D,"CBU",'手机&平板保底版销售计划数量VS 实际出货'!E:E,"FP") -> 0 | AM35: =SUMIFS('手机&平板保底版销售计划数量VS 实际出货'!S:S,'手机&平板保底版销售计划数量VS 实际出货'!D:D,"CBU",'手机&平板保底版销售计划数量VS 实际出货'!E:E,"FP") -> 0 | AN35: =SUMIFS('手机&平板保底版销售计划数量VS 实际出货'!U:U,'手机&平板保底版销售计划数量VS 实际出货'!D:D,"CBU",'手机&平板保底版销售计划数量VS 实际出货'!E:E,"FP") -> 0 | AO35: =SUMIFS('手机&平板保底版销售计划数量VS 实际出货'!W:W,'手机&平板保底版销售计划数量VS 实际出货'!D:D,"CBU",'手机&平板保底版销售计划数量VS 实际出货'!E:E,"FP") -> 0 | AP35: =SUMIFS('手机&平板保底版销售计划数量VS 实际出货'!Y:Y,'手机&平板保底版销售计划数量VS 实际出货'!D:D,"CBU",'手机&平板保底版销售计划数量VS 实际出货'!E:E,"FP") -> 0 | AQ35: =SUMIFS('手机&平板保底版销售计划数量VS 实际出货'!AA:AA,'手机&平板保底版销售计划数量VS 实际出货'!D:D,"CBU",'手机&平板保底版销售计划数量VS 实际出货'!E:E,"FP") -> 0 | AR35: =SUMIFS('手机&平板保底版销售计划数量VS 实际出货'!AC:AC,'手机&平板保底版销售计划数量VS 实际出货'!D:D,"CBU",'手机&平板保底版销售计划数量VS 实际出货'!E:E,"FP") -> 0 | AS35: =SUM(AG35:AR35) -> 10000
B36: SP | C36: =SUMIF('手机&平板保底版销售计划数量VS 实际出货'!E:E,B36,'手机&平板保底版销售计划数量VS 实际出货'!G:G) -> 575883 | D36: =SUMIF('手机&平板保底版销售计划数量VS 实际出货'!E:E,B36,'手机&平板保底版销售计划数量VS 实际出货'!H:H) -> 542057 | E36: =SUMIF('手机&平板保底版销售计划数量VS 实际出货'!E:E,B36,'手机&平板保底版销售计划数量VS 实际出货'!I:I) -> 331044 | F36: =SUMIF('手机&平板保底版销售计划数量VS 实际出货'!E:E,B36,'手机&平板保底版销售计划数量VS 实际出货'!J:J) -> 338076 | G36: =SUMIF('手机&平板保底版销售计划数量VS 实际出货'!E:E,B36,'手机&平板保底版销售计划数量VS 实际出货'!K:K) -> 600713 | H36: =SUMIF('手机&平板保底版销售计划数量VS 实际出货'!E:E,B36,'手机&平板保底版销售计划数量VS 实际出货'!L:L) -> 506109 | I36: =SUMIF('手机&平板保底版销售计划数量VS 实际出货'!E:E,B36,'手机&平板保底版销售计划数量VS 实际出货'!M:M) -> 343258 | J36: =SUMIF('手机&平板保底版销售计划数量VS 实际出货'!E:E,B36,'手机&平板保底版销售计划数量VS 实际出货'!N:N) -> 430182 | K36: =SUMIF('手机&平板保底版销售计划数量VS 实际出货'!E:E,B36,'手机&平板保底版销售计划数量VS 实际出货'!O:O) -> 925000 | L36: =SUMIF('手机&平板保底版销售计划数量VS 实际出货'!E:E,B36,'手机&平板保底版销售计划数量VS 实际出货'!P:P) -> 683925 | M36: =SUMIF('手机&平板保底版销售计划数量VS 实际出货'!E:E,B36,'手机&平板保底版销售计划数量VS 实际出货'!Q:Q) -> 860000 | N36: =SUMIF('手机&平板保底版销售计划数量VS 实际出货'!E:E,B36,'手机&平板保底版销售计划数量VS 实际出货'!R:R) -> 788295 | O36: =SUMIF('手机&平板保底版销售计划数量VS 实际出货'!E:E,B36,'手机&平板保底版销售计划数量VS 实际出货'!S:S) -> 1135000 | P36: =SUMIF('手机&平板保底版销售计划数量VS 实际出货'!E:E,B36,'手机&平板保底版销售计划数量VS 实际出货'!T:T) -> 950878 | Q36: =SUMIF('手机&平板保底版销售计划数量VS 实际出货'!E:E,B36,'手机&平板保底版销售计划数量VS 实际出货'!U:U) -> 1265000 | R36: =SUMIF('手机&平板保底版销售计划数量VS 实际出货'!E:E,B36,'手机&平板保底版销售计划数量VS 实际出货'!V:V) -> 878535 | S36: =SUMIF('手机&平板保底版销售计划数量VS 实际出货'!E:E,B36,'手机&平板保底版销售计划数量VS 实际出货'!W:W) -> 1277422 | T36: =SUMIF('手机&平板保底版销售计划数量VS 实际出货'!E:E,B36,'手机&平板保底版销售计划数量VS 实际出货'!X:X) -> 1523332 | U36: =SUMIF('手机&平板保底版销售计划数量VS 实际出货'!E:E,B36,'手机&平板保底版销售计划数量VS 实际出货'!Y:Y) -> 1285000 | V36: =SUMIF('手机&平板保底版销售计划数量VS 实际出货'!E:E,B36,'手机&平板保底版销售计划数量VS 实际出货'!Z:Z) -> 816412 | W36: =SUMIF('手机&平板保底版销售计划数量VS 实际出货'!E:E,B36,'手机&平板保底版销售计划数量VS 实际出货'!AA:AA) -> 1135000 | X36: =SUMIF('手机&平板保底版销售计划数量VS 实际出货'!E:E,B36,'手机&平板保底版销售计划数量VS 实际出货'!AB:AB) -> 848614 | Y36: =SUMIF('手机&平板保底版销售计划数量VS 实际出货'!E:E,B36,'手机&平板保底版销售计划数量VS 实际出货'!AC:AC) -> 1137750 | Z36: =SUMIF('手机&平板保底版销售计划数量VS 实际出货'!E:E,B36,'手机&平板保底版销售计划数量VS 实际出货'!AD:AD) -> 940659 | AA36: =C36+E36+G36+I36+K36+M36+O36+Q36+S36+U36+W36+Y36 -> 10871070 | AB36: =D36+F36+H36+J36+L36+N36+P36+R36+T36+V36+X36+Z36 -> 9247074 | AF36: CBU/SP | AG36: =SUMIFS('手机&平板保底版销售计划数量VS 实际出货'!G:G,'手机&平板保底版销售计划数量VS 实际出货'!D:D,"CBU",'手机&平板保底版销售计划数量VS 实际出货'!E:E,"SP") -> 447243 | AH36: =SUMIFS('手机&平板保底版销售计划数量VS 实际出货'!I:I,'手机&平板保底版销售计划数量VS 实际出货'!D:D,"CBU",'手机&平板保底版销售计划数量VS 实际出货'!E:E,"SP") -> 265544 | AI36: =SUMIFS('手机&平板保底版销售计划数量VS 实际出货'!K:K,'手机&平板保底版销售计划数量VS 实际出货'!D:D,"CBU",'手机&平板保底版销售计划数量VS 实际出货'!E:E,"SP") -> 442713 | AJ36: =SUMIFS('手机&平板保底版销售计划数量VS 实际出货'!M:M,'手机&平板保底版销售计划数量VS 实际出货'!D:D,"CBU",'手机&平板保底版销售计划数量VS 实际出货'!E:E,"SP") -> 263258 | AK36: =SUMIFS('手机&平板保底版销售计划数量VS 实际出货'!O:O,'手机&平板保底版销售计划数量VS 实际出货'!D:D,"CBU",'手机&平板保底版销售计划数量VS 实际出货'!E:E,"SP") -> 795000 | AL36: =SUMIFS('手机&平板保底版销售计划数量VS 实际出货'!Q:Q,'手机&平板保底版销售计划数量VS 实际出货'!D:D,"CBU",'手机&平板保底版销售计划数量VS 实际出货'!E:E,"SP") -> 700000 | AM36: =SUMIFS('手机&平板保底版销售计划数量VS 实际出货'!S:S,'手机&平板保底版销售计划数量VS 实际出货'!D:D,"CBU",'手机&平板保底版销售计划数量VS 实际出货'!E:E,"SP") -> 905000 | AN36: =SUMIFS('手机&平板保底版销售计划数量VS 实际出货'!U:U,'手机&平板保底版销售计划数量VS 实际出货'!D:D,"CBU",'手机&平板保底版销售计划数量VS 实际出货'!E:E,"SP") -> 1125000 | AO36: =SUMIFS('手机&平板保底版销售计划数量VS 实际出货'!W:W,'手机&平板保底版销售计划数量VS 实际出货'!D:D,"CBU",'手机&平板保底版销售计划数量VS 实际出货'!E:E,"SP") -> 1027422 | AP36: =SUMIFS('手机&平板保底版销售计划数量VS 实际出货'!Y:Y,'手机&平板保底版销售计划数量VS 实际出货'!D:D,"CBU",'手机&平板保底版销售计划数量VS 实际出货'!E:E,"SP") -> 1005000 | AQ36: =SUMIFS('手机&平板保底版销售计划数量VS 实际出货'!AA:AA,'手机&平板保底版销售计划数量VS 实际出货'!D:D,"CBU",'手机&平板保底版销售计划数量VS 实际出货'!E:E,"SP") -> 845000 | AR36: =SUMIFS('手机&平板保底版销售计划数量VS 实际出货'!AC:AC,'手机&平板保底版销售计划数量VS 实际出货'!D:D,"CBU",'手机&平板保底版销售计划数量VS 实际出货'!E:E,"SP") -> 897750 | AS36: =SUM(AG36:AR36) -> 8718930
B37: Total | C37: =SUM(C34:C36) -> 2129871 | D37: =SUM(D34:D36) -> 2253215 | E37: =SUM(E34:E36) -> 1774948 | F37: =SUM(F34:F36) -> 1369112 | G37: =SUM(G34:G36) -> 1973093 | H37: =SUM(H34:H36) -> 1551175 | I37: =SUM(I34:I36) -> 1663731 | J37: =SUM(J34:J36) -> 1314512 | ... AB37: =SUM(AB34:AB36) -> 23958863 | AF37: SKD/FP | AG37: =SUMIFS('手机&平板保底版销售计划数量VS 实际出货'!G:G,'手机&平板保底版销售计划数量VS 实际出货'!D:D,"SKD",'手机&平板保底版销售计划数量VS 实际出货'!E:E,"FP") -> 0 | AH37: =SUMIFS('手机&平板保底版销售计划数量VS 实际出货'!I:I,'手机&平板保底版销售计划数量VS 实际出货'!D:D,"SKD",'手机&平板保底版销售计划数量VS 实际出货'!E:E,"FP") -> 100000 | AI37: =SUMIFS('手机&平板保底版销售计划数量VS 实际出货'!K:K,'手机&平板保底版销售计划数量VS 实际出货'!D:D,"SKD",'手机&平板保底版销售计划数量VS 实际出货'!E:E,"FP") -> 100000 | AJ37: =SUMIFS('手机&平板保底版销售计划数量VS 实际出货'!M:M,'手机&平板保底版销售计划数量VS 实际出货'!D:D,"SKD",'手机&平板保底版销售计划数量VS 实际出货'!E:E,"FP") -> 150000 | AK37: =SUMIFS('手机&平板保底版销售计划数量VS 实际出货'!O:O,'手机&平板保底版销售计划数量VS 实际出货'!D:D,"SKD",'手机&平板保底版销售计划数量VS 实际出货'!E:E,"FP") -> 50000 | AL37: =SUMIFS('手机&平板保底版销售计划数量VS 实际出货'!Q:Q,'手机&平板保底版销售计划数量VS 实际出货'!D:D,"SKD",'手机&平板保底版销售计划数量VS 实际出货'!E:E,"FP") -> 100000 | AM37: =SUMIFS('手机&平板保底版销售计划数量VS 实际出货'!S:S,'手机&平板保底版销售计划数量VS 实际出货'!D:D,"SKD",'手机&平板保底版销售计划数量VS 实际出货'!E:E,"FP") -> 150000 | AN37: =SUMIFS('手机&平板保底版销售计划数量VS 实际出货'!U:U,'手机&平板保底版销售计划数量VS 实际出货'!D:D,"SKD",'手机&平板保底版销售计划数量VS 实际出货'!E:E,"FP") -> 50000 | AO37: =SUMIFS('手机&平板保底版销售计划数量VS 实际出货'!W:W,'手机&平板保底版销售计划数量VS 实际出货'!D:D,"SKD",'手机&平板保底版销售计划数量VS 实际出货'!E:E,"FP") -> 100000 | AP37: =SUMIFS('手机&平板保底版销售计划数量VS 实际出货'!G:G,'手机&平板保底版销售计划数量VS 实际出货'!Y:Y,"SKD",'手机&平板保底版销售计划数量VS 实际出货'!E:E,"FP") -> 0 | AQ37: =SUMIFS('手机&平板保底版销售计划数量VS 实际出货'!AA:AA,'手机&平板保底版销售计划数量VS 实际出货'!D:D,"SKD",'手机&平板保底版销售计划数量VS 实际出货'!E:E,"FP") -> 36000 | AR37: =SUMIFS('手机&平板保底版销售计划数量VS 实际出货'!AC:AC,'手机&平板保底版销售计划数量VS 实际出货'!D:D,"SKD",'手机&平板保底版销售计划数量VS 实际出货'!E:E,"FP") -> 0 | AS37: =SUM(AG37:AR37) -> 836000
AF38: SKD/SP | AG38: =SUMIFS('手机&平板保底版销售计划数量VS 实际出货'!G:G,'手机&平板保底版销售计划数量VS 实际出货'!D:D,"SKD",'手机&平板保底版销售计划数量VS 实际出货'!E:E,"SP") -> 44140 | AH38: =SUMIFS('手机&平板保底版销售计划数量VS 实际出货'!I:I,'手机&平板保底版销售计划数量VS 实际出货'!D:D,"SKD",'手机&平板保底版销售计划数量VS 实际出货'!E:E,"SP") -> 0 | AI38: =SUMIFS('手机&平板保底版销售计划数量VS 实际出货'!K:K,'手机&平板保底版销售计划数量VS 实际出货'!D:D,"SKD",'手机&平板保底版销售计划数量VS 实际出货'!E:E,"SP") -> 82500 | AJ38: =SUMIFS('手机&平板保底版销售计划数量VS 实际出货'!M:M,'手机&平板保底版销售计划数量VS 实际出货'!D:D,"SKD",'手机&平板保底版销售计划数量VS 实际出货'!E:E,"SP") -> 10000 | AK38: =SUMIFS('手机&平板保底版销售计划数量VS 实际出货'!O:O,'手机&平板保底版销售计划数量VS 实际出货'!D:D,"SKD",'手机&平板保底版销售计划数量VS 实际出货'!E:E,"SP") -> 60000 | AL38: =SUMIFS('手机&平板保底版销售计划数量VS 实际出货'!Q:Q,'手机&平板保底版销售计划数量VS 实际出货'!D:D,"SKD",'手机&平板保底版销售计划数量VS 实际出货'!E:E,"SP") -> 70000 | AM38: =SUMIFS('手机&平板保底版销售计划数量VS 实际出货'!S:S,'手机&平板保底版销售计划数量VS 实际出货'!D:D,"SKD",'手机&平板保底版销售计划数量VS 实际出货'!E:E,"SP") -> 120000 | AN38: =SUMIFS('手机&平板保底版销售计划数量VS 实际出货'!U:U,'手机&平板保底版销售计划数量VS 实际出货'!D:D,"SKD",'手机&平板保底版销售计划数量VS 实际出货'!E:E,"SP") -> 80000 | AO38: =SUMIFS('手机&平板保底版销售计划数量VS 实际出货'!W:W,'手机&平板保底版销售计划数量VS 实际出货'!D:D,"SKD",'手机&平板保底版销售计划数量VS 实际出货'!E:E,"SP") -> 70000 | AP38: =SUMIFS('手机&平板保底版销售计划数量VS 实际出货'!Y:Y,'手机&平板保底版销售计划数量VS 实际出货'!D:D,"SKD",'手机&平板保底版销售计划数量VS 实际出货'!E:E,"SP") -> 70000 | AQ38: =SUMIFS('手机&平板保底版销售计划数量VS 实际出货'!AA:AA,'手机&平板保底版销售计划数量VS 实际出货'!D:D,"SKD",'手机&平板保底版销售计划数量VS 实际出货'!E:E,"SP") -> 40000 | AR38: =SUMIFS('手机&平板保底版销售计划数量VS 实际出货'!AC:AC,'手机&平板保底版销售计划数量VS 实际出货'!D:D,"SKD",'手机&平板保底版销售计划数量VS 实际出货'!E:E,"SP") -> 60000 | AS38: =SUM(AG38:AR38) -> 706640
AF39: CKD | AG39: =SUMIF('手机&平板保底版销售计划数量VS 实际出货'!D:D,"CKD",'手机&平板保底版销售计划数量VS 实际出货'!G:G) -> 1520000 | AH39: =SUMIF('手机&平板保底版销售计划数量VS 实际出货'!D:D,"CKD",'手机&平板保底版销售计划数量VS 实际出货'!I:I) -> 1300000 | AI39: =SUMIF('手机&平板保底版销售计划数量VS 实际出货'!D:D,"CKD",'手机&平板保底版销售计划数量VS 实际出货'!K:K) -> 1210000 | AJ39: =SUMIF('手机&平板保底版销售计划数量VS 实际出货'!D:D,"CKD",'手机&平板保底版销售计划数量VS 实际出货'!M:M) -> 1160000 | AK39: =SUMIF('手机&平板保底版销售计划数量VS 实际出货'!D:D,"CKD",'手机&平板保底版销售计划数量VS 实际出货'!O:O) -> 1320000 | AL39: =SUMIF('手机&平板保底版销售计划数量VS 实际出货'!D:D,"CKD",'手机&平板保底版销售计划数量VS 实际出货'!Q:Q) -> 1310000 | AM39: =SUMIF('手机&平板保底版销售计划数量VS 实际出货'!D:D,"CKD",'手机&平板保底版销售计划数量VS 实际出货'!S:S) -> 1590000 | AN39: =SUMIF('手机&平板保底版销售计划数量VS 实际出货'!D:D,"CKD",'手机&平板保底版销售计划数量VS 实际出货'!U:U) -> 1550000 | AO39: =SUMIF('手机&平板保底版销售计划数量VS 实际出货'!D:D,"CKD",'手机&平板保底版销售计划数量VS 实际出货'!W:W) -> 1740000 | AP39: =SUMIF('手机&平板保底版销售计划数量VS 实际出货'!D:D,"CKD",'手机&平板保底版销售计划数量VS 实际出货'!Y:Y) -> 1760000 | AQ39: =SUMIF('手机&平板保底版销售计划数量VS 实际出货'!D:D,"CKD",'手机&平板保底版销售计划数量VS 实际出货'!AA:AA) -> 1160000 | AR39: =SUMIF('手机&平板保底版销售计划数量VS 实际出货'!D:D,"CKD",'手机&平板保底版销售计划数量VS 实际出货'!AC:AC) -> 1083000 | AS39: =SUM(AG39:AR39) -> 16703000
AF40: Total | AG40: =SUM(AG34:AG39) -> 2011383 | AH40: =SUM(AH34:AH39) -> 1675544 | AI40: =SUM(AI34:AI39) -> 1845213 | AJ40: =SUM(AJ34:AJ39) -> 1583258 | AK40: =SUM(AK34:AK39) -> 2225000 | AL40: =SUM(AL34:AL39) -> 2180000 | AM40: =SUM(AM34:AM39) -> 2765000 | AN40: =SUM(AN34:AN39) -> 2805000 | ... AS40: =SUM(AS34:AS39) -> 26984570

Sheet 目标完成
B2: 客户 | C2: 1-10月份 | G2: 10月份 | K2: 1-12月份 | O2: 2021年全年
C3: 分解目标 | D3: 实际完成 | E3: 差异 | F3: 完成率 | G3: 分解目标 | H3: 实际完成 | I3: 差异 | J3: 完成率 | K3: 分解目标 | L3: 最新销售计划 | M3: 差异 | N3: 预计完成率 | O3: 年度目标 | P3: 截至10月底 完成率 | Q3: 截至10月底预计完成率
B4: 汇总 | C4: =SUM(C5:C17) -> 110197.73 | D4: =SUM(D5:D17) -> 89155.548 | E4: =D4-C4 -> -21042.178 | F4: =D4/C4 -> 0.80905071 | G4: =SUM(G5:G17) -> 15886.878 | H4: =SUM(H5:H17) -> 6844 | I4: =H4-G4 -> -9042.8775 | J4: =H4/G4 -> 0.43079579 | K4: =SUM(K5:K17) -> 181942.78 | L4: =SUM(L5:L17) -> #REF! | M4: =L4-K4 -> #REF! | N4: =L4/K4 -> #REF! | O4: =SUM(O5:O17) -> 181942.78 | P4: =D4/O4 -> 0.49001972 | Q4: =L4/O4 -> #REF!
B5: LAVA | C5: 27475.113 | D5: 22499.894 | E5: =D5-C5 -> -4975.2187 | F5: =D5/C5 -> 0.81891908 | G5: 5766.215 | H5: 1462 | I5: =H5-G5 -> -4304.215 | J5: =H5/G5 -> 0.25354587 | K5: 52553.413 | L5: =D5+SUMIF(#REF!,B5,#REF!) -> #REF! | M5: =L5-K5 -> #REF! | N5: =L5/K5 -> #REF! | O5: 52553.413 | P5: =D5/O5 -> 0.42813384 | Q5: =L5/O5 -> #REF!
B6: HMD | C6: 15713.442 | D6: 14125.723 | E6: =D6-C6 -> -1587.7189 | F6: =D6/C6 -> 0.89895792 | G6: 1912.3325 | H6: 84 | I6: =H6-G6 -> -1828.3325 | J6: =H6/G6 -> 0.043925416 | K6: 23362.772 | L6: =D6+SUMIF(#REF!,B6,#REF!) -> #REF! | M6: =L6-K6 -> #REF! | N6: =L6/K6 -> #REF! | O6: 23362.772 | P6: =D6/O6 -> 0.6046253 | Q6: =L6/O6 -> #REF!
B7: SM | C7: 16331.121 | D7: 11473.075 | E7: =D7-C7 -> -4858.0465 | F7: =D7/C7 -> 0.70252829 | G7: 2618.2 | H7: 148 | I7: =H7-G7 -> -2470.2 | J7: =H7/G7 -> 0.056527385 | K7: 26052.521 | L7: =D7+SUMIF(#REF!,B7,#REF!) -> #REF! | M7: =L7-K7 -> #REF! | N7: =L7/K7 -> #REF! | O7: 26052.521 | P7: =D7/O7 -> 0.44038251 | Q7: =L7/O7 -> #REF!
B8: BLU | C8: 8863.8755 | D8: 7090.5726 | E8: =D8-C8 -> -1773.303 | F8: =D8/C8 -> 0.79994045 | G8: 721.825 | H8: 518 | I8: =H8-G8 -> -203.825 | J8: =H8/G8 -> 0.71762546 | K8: 13701.176 | L8: =D8+SUMIF(#REF!,B8,#REF!) -> #REF! | M8: =L8-K8 -> #REF! | N8: =L8/K8 -> #REF! | O8: 13701.176 | P8: =D8/O8 -> 0.51751564 | Q8: =L8/O8 -> #REF!
