Workbook

Sheet Sheet1
B1: Q1 | C1: Jan | D1: Feb | E1: Mar
A2: 2025年计划出货金额 | B2: =SUM(C2:E2) -> 73367.353 | C2: ='2025数据'!D4 -> 25825.754 | D2: ='2025数据'!E4 -> 20298.077 | E2: ='2025数据'!F4 -> 27243.522
A3: 2024年实际出货金额 | B3: =SUM(C3:E3) -> 62546.622 | C3: 28412.634 | D3: 13508.416 | E3: 20625.572
B6: Q2 | C6: Apr | D6: May | E6: Jun
A7: 2025年实际+计划出货金额 | B7: =SUM(C7:E7) -> #REF! | C7: ='2025数据'!G4 -> 19367.918 | D7: ='2025数据'!H4 -> 25916.611 | E7: ='2025数据'!#REF! -> #REF!
A8: 2024年实际出货金额 | B8: =SUM(C8:E8) -> 55199.486 | C8: 16661.011 | D8: 18784.733 | E8: 19753.742
B11: Q3 | C11: Jul | D11: Aug | E11: Sep
A12: 2025年计划出货金额 | B12: =SUM(C12:E12) -> #REF! | C12: ='2025数据'!#REF! -> #REF! | D12: ='2025数据'!#REF! -> #REF! | E12: ='2025数据'!#REF! -> #REF!
A13: 2024年实际出货金额 | B13: =SUM(C13:E13) -> 84842.796 | C13: 25131.841 | D13: 34901.789 | E13: 24809.166

Sheet 2025数据
B2: 客户 | C2: 1-12月 | D2: 1月份 | E2: 2月份 | F2: 3月份 | G2: 4月 | H2: 5月 | I2: 6月 | J2: 7月 | K2: 8月 | L2: 9月 | M2: 10月 | N2: 11月 | O2: 12月
C3: 实际出货合计 | D3: 实际出货 | E3: 实际出货 | F3: 实际出货 | G3: 实际出货 | H3: 实际出货 | I3: 实际出货 | J3: 实际出货 | K3: 实际出货 | L3: 实际出货 | M3: 实际出货 | N3: 实际出货 | O3: 实际出货 | S3: 年度占比 | T3: local客户占比
B4: 汇总 | C4: =SUM(C5:C44) -> 417096.72 | D4: =SUM(D5:D44) -> 25825.754 | E4: =SUM(E5:E44) -> 20298.077 | F4: =SUM(F5:F44) -> 27243.522 | G4: =SUM(G5:G44) -> 19367.918 | H4: =SUM(H5:H44) -> 25916.611 | I4: =SUM(I5:I44) -> 29144.099 | J4: =SUM(J5:J44) -> 47587.766 | ... O4: =SUM(O5:O44) -> 33248.237
A5: Javi | B5: HMD | C5: =SUM(D5:O5) -> 46476.768 | D5: 5561.0166 | E5: 3220.421 | F5: 3883.7571 | G5: 3271.9787 | H5: 3559.2678 | I5: 2596.6914 | J5: 3185.5075 | K5: 2427.4487 | L5: 3569.8814 | M5: 4004.002 | N5: 5518.0386 | O5: 5678.7575 | S5: =C5/$C$4 -> 0.11142923
A6: Steve | B6: ZTE | C6: =SUM(D6:O6) -> 107762.61 | D6: 6745.6604 | E6: 4867.1323 | F6: 6006.1922 | G6: 5213.5715 | H6: 8344.746 | I6: 8620.971 | J6: 9882.299 | K6: 9594.285 | L6: 15052.685 | M6: 9604.8149 | N6: 11152.464 | O6: 12677.789 | S6: =C6/$C$4 -> 0.2583636
A7: Diana | B7: LAVA | C7: =SUM(D7:O7) -> 30597.259 | D7: 1517.5824 | E7: 1482.1056 | F7: 1416.8027 | G7: 2879.9263 | H7: 3111.808 | I7: 2366.4397 | J7: 2048.5768 | K7: 5414.076 | L7: 7041.4312 | M7: 1116.1987 | N7: 1405.6306 | O7: 796.68117 | S7: =C7/$C$4 -> 0.073357707 | T7: =C7/$C$64 -> 0.33751511
A8: Arthur | B8: SM | C8: =SUM(D8:O8) -> 1016.64 | F8: 662.4 | G8: 354.24 | S8: =C8/$C$4 -> 0.0024374203 | T8: =C8/$C$64 -> 0.011214448
A9: Sam | B9: BLU | C9: =SUM(D9:O9) -> 13164.286 | D9: 1091.5066 | F9: 1000.5601 | H9: 1481.8425 | I9: 1090.2934 | J9: 2576.0044 | K9: 736.032 | L9: 380.54976 | M9: 1902.375 | N9: 1735.5561 | O9: 1169.566 | S9: =C9/$C$4 -> 0.03156171 | T9: =C9/$C$64 -> 0.14521384
A10: Java | B10: Doro | C10: =SUM(D10:O10) -> 86.086 | D10: 42.742 | E10: 43.344 | S10: =C10/$C$4 -> 0.00020639338 | T10: =C10/$C$64 -> 0.00094960551
A11: Steve | B11: MBC | C11: =SUM(D11:O11) -> 2625.2978 | D11: 644.68 | F11: 620.1 | G11: 388.8 | H11: 292.75425 | I11: 678.9636 | S11: =C11/$C$4 -> 0.0062942184 | T11: =C11/$C$64 -> 0.028959381
B12: PT | C12: =SUM(D12:O12) -> 0 | S12: =C12/$C$4 -> 0 | T12: =C12/$C$64 -> 0
B13: LF | C13: =SUM(D13:O13) -> 3533.5658 | D13: 1083.2825 | F13: 964.764 | H13: 174.09842 | I13: 440.55038 | J13: 110.09861 | L13: 0 | M13: 760.77188 | S13: =C13/$C$4 -> 0.0084718139 | T13: =C13/$C$64 -> 0.038978388
B14: YTF | C14: =SUM(D14:O14) -> 2588.1757 | D14: 396.4995 | G14: 70.956 | H14: 329.52418 | I14: 368.40349 | L14: 1214.4198 | M14: 208.37276 | S14: =C14/$C$4 -> 0.0062052172 | T14: =C14/$C$64 -> 0.028549891
B15: AI | C15: =SUM(D15:O15) -> 25303.472 | H15: 47.62078 | I15: 2460.8021 | J15: 6751.6414 | K15: 2741.1728 | L15: 9756.7344 | M15: 2872.359 | O15: 673.1413 | S15: =C15/$C$4 -> 0.060665717 | T15: =C15/$C$64 -> 0.27911991
B16: GDL | C16: =SUM(D16:O16) -> 2172.5776 | G16: 332.28 | I16: 330.5008 | J16: 628.29375 | K16: 277.89696 | L16: 603.60608 | S16: =C16/$C$4 -> 0.00520881 | T16: =C16/$C$64 -> 0.023965472
B17: WIKO | C17: =SUM(D17:O17) -> 164.29968 | G17: 164.29968 | S17: =C17/$C$4 -> 0.00039391266 | T17: =C17/$C$64 -> 0.0018123723
B18: TP | C18: =SUM(D18:O18) -> 3060.626 | E18: 133.488 | F18: 311.472 | H18: 166.54464 | I18: 7.687736 | K18: 1239.6359 | L18: 741.67295 | N18: 153.16655 | O18: 306.9583 | S18: =C18/$C$4 -> 0.0073379288 | T18: =C18/$C$64 -> 0.03376144
A19: Jackson | B19: XM | C19: =SUM(D19:O19) -> 1065.3848 | D19: 665.4688 | N19: 200.90678 | O19: 199.00919 | S19: =C19/$C$4 -> 0.0025542871 | T19: =C19/$C$64 -> 0.011752146
B20: GV | C20: =SUM(D20:O20) -> 2138.4286 | H20: 355.8952 | J20: 285.42487 | L20: 353.46944 | N20: 279.90548 | O20: 863.73365 | S20: =C20/$C$4 -> 0.0051269371 | T20: =C20/$C$64 -> 0.023588779
B21: VGT | C21: =SUM(D21:O21) -> 659.26976 | H21: 0 | N21: 659.26976 | O21: 0 | S21: =C21/$C$4 -> 0.001580616 | T21: =C21/$C$64 -> 0.0072723346
B22: ST | C22: =SUM(D22:O22) -> 161.8533 | H22: 0 | O22: 161.8533 | S22: =C22/$C$4 -> 0.0003880474 | T22: =C22/$C$64 -> 0.0017853865
B23: SL | C23: =SUM(D23:O23) -> 0 | H23: 0 | S23: =C23/$C$4 -> 0 | T23: =C23/$C$64 -> 0
B24: Assr | C24: =SUM(D24:O24) -> 156.978 | H24: 0 | M24: 156.978 | S24: =C24/$C$4 -> 0.00037635875 | T24: =C24/$C$64 -> 0.0017316076
B25: SK | C25: =SUM(D25:O25) -> 375.73944 | H25: 0 | L25: 375.73944 | S25: =C25/$C$4 -> 0.00090084487 | T25: =C25/$C$64 -> 0.0041447418
B26: ET | C26: =SUM(D26:O26) -> 970.65949 | H26: 0 | N26: 970.65949 | O26: 0 | S26: =C26/$C$4 -> 0.0023271808 | T26: =C26/$C$64 -> 0.010707242
B27: MC | C27: =SUM(D27:O27) -> 813.888 | F27: 813.888 | S27: =C27/$C$4 -> 0.0019513172 | T27: =C27/$C$64 -> 0.0089779119
A28: Javi | B28: ZYB | C28: =SUM(D28:O28) -> 100904.67 | D28: 4648.7787 | E28: 4636.6923 | F28: 3595 | G28: 3698.7434 | H28: 5045.8775 | I28: 5957.6133 | J28: 10979.764 | K28: 20464.531 | L28: 21374.31 | M28: 9461.6003 | N28: 7616.0244 | O28: 3425.7312 | S28: =C28/$C$4 -> 0.2419215
A29: Jackson | B29: Xiaodu | C29: =SUM(D29:O29) -> 4730.0668 | D29: 1288.8235 | E29: 605.51327 | F29: 1803.115 | K29: 710.23621 | L29: 322.37883 | S29: =C29/$C$4 -> 0.011340456
B30: TAL | C30: =SUM(D30:O30) -> 2551.6793 | D30: 51.36869 | E30: 712.08319 | F30: 1429.7009 | H30: 149.43387 | L30: 209.09268 | S30: =C30/$C$4 -> 0.0061177161
B31: KK | C31: =SUM(D31:O31) -> 1042.5619 | D31: 0 | E31: 0 | F31: 0 | H31: 417.06903 | I31: 451.82478 | L31: 173.66814 | S31: =C31/$C$4 -> 0.0024995688
A32: Diana | B32: Didi | C32: =SUM(D32:O32) -> 6707.4011 | D32: 346.54324 | E32: 1067.9577 | F32: 954.26 | G32: 626.52033 | H32: 658.70141 | I32: 409.37981 | J32: 427.34912 | K32: 275.92837 | L32: 100.09924 | M32: 507.97985 | N32: 629.32835 | O32: 703.35364 | S32: =C32/$C$4 -> 0.016081165
A33: Steve | B33: MT | C33: =SUM(D33:O33) -> 16477.892 | D33: 1493.409 | E33: 3016.963 | F33: 3113.41 | G33: 2366.6023 | H33: 1393.7418 | I33: 1353.14 | J33: 1649.2979 | K33: 1010.0768 | L33: 361.5248 | M33: 173.94229 | N33: 142.15003 | O33: 403.63399 | S33: =C33/$C$4 -> 0.039506165
B34: 哈啰 | C34: =SUM(D34:O34) -> 1047.3356 | D34: 164.12177 | E34: 354.01381 | F34: 529.2 | S34: =C34/$C$4 -> 0.0025110137
A35: Sam | B35: 德卡 | C35: =SUM(D35:O35) -> 124.78 | F35: 124.78 | S35: =C35/$C$4 -> 0.00029916322
A36: Sam | B36: 巨鼎 | C36: =SUM(D36:O36) -> 693.48867 | E36: 158.36283 | I36: 178.10735 | N36: 357.0185 | O36: 0 | S36: =C36/$C$4 -> 0.0016626567
A37: Java | B37: 艾康 | C37: =SUM(D37:O37) -> 253.85124 | J37: 253.85124 | S37: =C37/$C$4 -> 0.0006086148
A38: Steve | B38: 天猫 | C38: =SUM(D38:O38) -> 49.872619 | D38: 5.272354 | F38: 7.91 | J38: 5.8704425 | K38: 11.740885 | L38: 11.740885 | M38: 7.3380531 | S38: =C38/$C$4 -> 0.00011957087
A39: Steve | B39: Webin | C39: =SUM(D39:O39) -> 29904.951 | D39: 78.99815 | H39: 328.31004 | I39: 1441.5354 | J39: 6432.2041 | K39: 5435.6208 | L39: 7985.3986 | M39: 1985.2244 | N39: 29.630886 | O39: 6188.0288 | S39: =C39/$C$4 -> 0.071697881
A40: Steve | B40: MY | C40: =SUM(D40:O40) -> 7698.9353 | H40: 59.376106 | I40: 391.19469 | J40: 2371.5828 | K40: 3974.614 | L40: 741.54814 | N40: 160.61947 | O40: 0 | S40: =C40/$C$4 -> 0.018458393
B41: TX | C41: =SUM(D41:O41) -> 0 | S41: =C41/$C$4 -> 0
...

Sheet Sheet2
A1: 类别 | B1: 2025年 | C1: 2025业务贡献度 | D1: 2024年 | E1: 2024业务贡献度 | F1: 增长额 | G1: 增长率 | H1: 业务贡献比变化
A2: ZTE | B2: 107762.61 | C2: =B2/$B$8 -> 0.2583636 | D2: 75882.882 | E2: =D2/$D$8 -> 0.28028871 | F2: =B2-D2 -> 31879.729 | G2: =F2/D2 -> 0.42011753 | H2: =C2-E2 -> -0.021925114
A3: HMD | B3: 46476.768 | C3: =B3/$B$8 -> 0.11142923 | D3: 80633.894 | E3: =D3/$D$8 -> 0.29783754 | F3: =B3-D3 -> -34157.125 | G3: =F3/D3 -> -0.42360754 | H3: =C3-E3 -> -0.1864083
A4: local | B4: 90654.487 | C4: =B4/$B$8 -> 0.21734644 | D4: 36786.379 | E4: =D4/$D$8 -> 0.1358779 | F4: =B4-D4 -> 53868.108 | G4: =F4/D4 -> 1.4643493 | H4: =C4-E4 -> 0.081468536
A5: 平板 | B5: 109228.97 | C5: =B5/$B$8 -> 0.26187924 | D5: 51904.342 | E5: =D5/$D$8 -> 0.19171915 | F5: =B5-D5 -> 57324.632 | G5: =F5/D5 -> 1.1044284 | H5: =C5-E5 -> 0.070160096
A6: 共享 | B6: 24232.629 | C6: =B6/$B$8 -> 0.058098344 | D6: 16966.701 | E6: =D6/$D$8 -> 0.062669931 | F6: =B6-D6 -> 7265.9272 | G6: =F6/D6 -> 0.42824631 | H6: =C6-E6 -> -0.0045715872
A7: others AIOT | B7: 38741.253 | C7: =B7/$B$8 -> 0.092883139 | D7: 8556.9363 | E7: =D7/$D$8 -> 0.031606769 | F7: =B7-D7 -> 30184.316 | G7: =F7/D7 -> 3.5274677 | H7: =C7-E7 -> 0.06127637
A8: 汇总 | B8: 417096.72 | D8: 270731.13 | F8: =B8-D8 -> 146365.59 | G8: =F8/D8 -> 0.54063079

Sheet Sheet3
A1: 区域 | B1: 出货金额
A2: 印度 | B2: 55902
A3: 美国 | B3: 13166
A4: 中东 | B4: 7102
A5: 拉美 | B5: 3534
A6: 孟加拉 | B6: 3189
A7: 南非 | B7: 2626
A8: 阿尔及利亚 | B8: 2138
A9: 巴基斯坦 | B9: 1724
A10: 越南 | B10: 814
A11: 肯尼亚 | B11: 376
A12: 瑞典 | B12: 86
B13: =SUM(B2:B12) -> 90657

Sheet 与年度目标对比
A2: 客户 | B2: 全年保底 | C2: 占比 | D2: Q1 | E2: Q1 | F2: 偏差 | G2: Q2 | H2: Q2 | I2: 偏差 | J2: Q3 | K2: Q3 | L2: 偏差 | M2: Q4 | O2: Q1+Q2+Q3 | P2: Q1+Q2+Q3 | Q2: 偏差 | R2: 年度目标完成率
B3: 目标分解 | D3: 目标分解 | E3: 实际达成 | G3: 目标分解 | H3: 计划 | J3: 目标分解 | K3: 计划 | M3: 目标分解 | O3: 目标分解 | P3: 实际&计划
A4: ZTE | B4: =B16 -> 123850.18 | C4: =B4/B15 -> 0.33681491 | D4: =C16 -> 18672.113 | E4: =D16 -> #REF! | F4: =E4-D4 -> #REF! | G4: =F16 -> 25162.182 | H4: ='2025数据'!C62+'2025数据'!#REF!-E4 -> #REF! | I4: =H4-G4 -> #REF! | J4: =I16 -> 42457.158 | K4: ='2025数据'!#REF!+'2025数据'!#REF!+'2025数据'!#REF! -> #REF! | L4: =K4-J4 -> #REF! | M4: =J16 -> 37558.725 | O4: =D4+G4+J4 -> 86291.453 | P4: =E4+H4+K4 -> #REF! | Q4: =P4-O4 -> #REF! | R4: =P4/B4 -> #REF!
A5: HMD | B5: =B17 -> 65416.12 | C5: =B5/367709.90128077 -> 0.17790144 | D5: =C17 -> 15695.4 | E5: =D17 -> #REF! | F5: =E5-D5 -> #REF! | G5: =F17 -> 15177.4 | H5: ='2025数据'!C63+'2025数据'!#REF!-E5 -> #REF! | I5: =H5-G5 -> #REF! | J5: =I17 -> 19693.8 | K5: ='2025数据'!#REF!+'2025数据'!#REF!+'2025数据'!#REF! -> #REF! | L5: =K5-J5 -> #REF! | M5: =J17 -> 14849.52 | O5: =D5+G5+J5 -> 50566.6 | P5: =E5+H5+K5 -> #REF! | Q5: =P5-O5 -> #REF! | R5: =P5/B5 -> #REF!
A6: local king 客户 | B6: =SUM(B18:B31) -> 86249.825 | C6: =B6/367709.90128077 -> 0.23455943 | D6: =SUM(C18:C31) -> 14273.819 | E6: =SUM(D18:D31) -> #REF! | F6: =E6-D6 -> #REF! | G6: =SUM(F18:F31) -> 19268.356 | H6: ='2025数据'!C64+'2025数据'!#REF!-E6 -> #REF! | I6: =H6-G6 -> #REF! | J6: =SUM(I18:I31) -> 25834.26 | K6: ='2025数据'!#REF!+'2025数据'!#REF!+'2025数据'!#REF! -> #REF! | L6: =K6-J6 -> #REF! | M6: =SUM(J18:J31) -> 26873.39 | O6: =D6+G6+J6 -> 59376.435 | P6: =E6+H6+K6 -> #REF! | Q6: =P6-O6 -> #REF! | R6: =P6/B6 -> #REF!
A7: 平板 | B7: =B32+B33+B35+B34 -> 61700.094 | C7: =B7/367709.90128077 -> 0.16779558 | D7: =C32+C33+C35+C34 -> 16877.753 | E7: =D32+D33+D35+D34 -> #REF! | F7: =E7-D7 -> #REF! | G7: =F32+F33+F35+F34 -> 14985.545 | H7: ='2025数据'!C65+'2025数据'!#REF!-E7 -> #REF! | I7: =H7-G7 -> #REF! | J7: =I32+I33+I35+I34 -> 15177.293 | K7: ='2025数据'!#REF!+'2025数据'!#REF!+'2025数据'!#REF! -> #REF! | L7: =K7-J7 -> #REF! | M7: =J32+J33+J35+J34 -> 14659.503 | O7: =D7+G7+J7 -> 47040.591 | P7: =E7+H7+K7 -> #REF! | Q7: =P7-O7 -> #REF! | R7: =P7/B7 -> #REF!
A8: 共享 | B8: =B36+B37+B38 -> 16496.309 | C8: =B8/367709.90128077 -> 0.044862291 | D8: =C36+C37+C38 -> 10370.151 | E8: =D36+D37+D38+D39 -> #REF! | F8: =E8-D8 -> #REF! | G8: =F36+F37+F38 -> 4634.5635 | H8: ='2025数据'!C66+'2025数据'!#REF!-E8 -> #REF! | I8: =H8-G8 -> #REF! | J8: =I36+I37+I38 -> 1303.4735 | K8: ='2025数据'!#REF!+'2025数据'!#REF!+'2025数据'!#REF! -> #REF! | L8: =K8-J8 -> #REF! | M8: =J36+J37+J38 -> 188.12018 | O8: =D8+G8+J8 -> 16308.188 | P8: =E8+H8+K8 -> #REF! | Q8: =P8-O8 -> #REF! | R8: =P8/B8 -> #REF!
A9: others | B9: =B42+B40+B41+B43+B44+B45+B46 -> 13997.375 | C9: =B9/367709.90128077 -> 0.038066354 | D9: =C42+C40+C41+C43+C44+C45+C46 -> 301.50982 | E9: =D42+D40+D41+D43+D44+D45+D46 -> #REF! | F9: =E9-D9 -> #REF! | G9: =F42+F40+F41+F43+F44+F45+F46 -> 2265.292 | H9: ='2025数据'!C67+'2025数据'!#REF!-E9 -> #REF! | I9: =H9-G9 -> #REF! | J9: =I42+I40+I41+I43+I44+I45+I46 -> 5130.4381 | K9: ='2025数据'!#REF!+'2025数据'!#REF!+'2025数据'!#REF! -> #REF! | L9: =K9-J9 -> #REF! | M9: =J42+J40+J41+J43+J44+J45+J46 -> 6300.1355 | O9: =D9+G9+J9 -> 7697.2399 | P9: =E9+H9+K9 -> #REF! | Q9: =P9-O9 -> #REF! | R9: =P9/B9 -> #REF!
A10: 合计 | B10: =SUM(B4:B9) -> 367709.9 | D10: =SUM(D4:D9) -> 76190.746 | E10: =SUM(E4:E9) -> #REF! | F10: =SUM(F4:F9) -> #REF! | G10: =SUM(G4:G9) -> 81493.338 | H10: =SUM(H4:H9) -> #REF! | I10: =SUM(I4:I9) -> #REF! | J10: =SUM(J4:J9) -> 109596.42 | K10: =SUM(K4:K9) -> #REF! | L10: =K10-J10 -> #REF! | M10: =SUM(M4:M9) -> 100429.39 | O10: =SUM(O4:O9) -> 267280.51 | P10: =SUM(P4:P9) -> #REF! | Q10: =P10-O10 -> #REF! | R10: =P10/B10 -> #REF!
D11: =D10/$B$10 -> 0.20720341 | E11: =E10/$B$10 -> #REF! | G11: =G10/$B$10 -> 0.221624 | H11: =H10/$B$10 -> #REF! | J11: =J10/$B$10 -> 0.29805132 | M11: =M10/$B$10 -> 0.27312127 | O11: =O10/$B$10 -> 0.72687873 | P11: =P10/$B$10 -> #REF!
A13: 客户 | B13: 全年保底 | C13: Q1 | D13: Q1 | E13: 偏差 | F13: Q2 | G13: Q2 | H13: 偏差 | I13: Q3 | J13: Q4 | M13: 目标分解占比 | N13: Q1完成占比 | O13: Q2计划占比
B14: 目标分解 | C14: 目标分解 | D14: 实际达成 | F14: 目标分解 | G14: 完成+计划 | I14: 目标分解 | J14: 目标分解
A15: 汇总 | B15: =SUM(B16:B46) -> 367709.9 | C15: =SUM(C16:C46) -> 76190.746 | D15: =SUM(D16:D46) -> #REF! | E15: =SUM(E16:E46) -> #REF! | F15: =SUM(F16:F46) -> 81493.338 | G15: =SUM(G16:G46) -> #REF! | H15: =SUM(H16:H46) -> #REF! | I15: =SUM(I16:I46) -> 109596.42 | J15: =SUM(J16:J46) -> 100429.39
A16: ZTE | B16: 123850.18 | C16: 18672.113 | D16: =VLOOKUP(A16,'2025数据'!B:D,5,0)+VLOOKUP(A16,'2025数据'!B:E,6,0)+VLOOKUP(A16,'2025数据'!B:O,7,0) -> #REF! | E16: =D16-C16 -> #REF! | F16: 25162.182 | G16: =VLOOKUP(A16,'2025数据'!B:O,18,0)+VLOOKUP(A16,'2025数据'!B:G,8,0)+VLOOKUP(A16,'2025数据'!B:O,17,0) -> #REF! | H16: =G16-F16 -> #REF! | I16: 42457.158 | J16: 37558.725
A17: HMD | B17: 65416.12 | C17: 15695.4 | D17: =VLOOKUP(A17,'2025数据'!B:D,5,0)+VLOOKUP(A17,'2025数据'!B:E,6,0)+VLOOKUP(A17,'2025数据'!B:O,7,0) -> #REF! | E17: =D17-C17 -> #REF! | F17: 15177.4 | G17: =VLOOKUP(A17,'2025数据'!B:O,18,0)+VLOOKUP(A17,'2025数据'!B:G,8,0)+VLOOKUP(A17,'2025数据'!B:O,17,0) -> #REF! | H17: =G17-F17 -> #REF! | I17: 19693.8 | J17: 14849.52
A18: BLU | B18: 5762.68 | C18: 2048.9 | D18: =VLOOKUP(A18,'2025数据'!B:D,5,0)+VLOOKUP(A18,'2025数据'!B:E,6,0)+VLOOKUP(A18,'2025数据'!B:O,7,0) -> #REF! | E18: =D18-C18 -> #REF! | F18: 1624.14 | G18: =VLOOKUP(A18,'2025数据'!B:O,18,0)+VLOOKUP(A18,'2025数据'!B:G,8,0)+VLOOKUP(A18,'2025数据'!B:O,17,0) -> #REF! | H18: =G18-F18 -> #REF! | I18: 1417.64 | J18: 672 | M18: =B18/$B$6 -> 0.066813817 | N18: =D18/$E$6 -> #REF! | O18: =G18/$H$6 -> #REF!
A19: LF | B19: 5635 | C19: 1820 | D19: =VLOOKUP(A19,'2025数据'!B:D,5,0)+VLOOKUP(A19,'2025数据'!B:E,6,0)+VLOOKUP(A19,'2025数据'!B:O,7,0) -> #REF! | E19: =D19-C19 -> #REF! | F19: 2450 | G19: =VLOOKUP(A19,'2025数据'!B:O,18,0)+VLOOKUP(A19,'2025数据'!B:G,8,0)+VLOOKUP(A19,'2025数据'!B:O,17,0) -> #REF! | H19: =G19-F19 -> #REF! | I19: 1050 | J19: 315 | M19: =B19/$B$6 -> 0.065333466 | N19: =D19/$E$6 -> #REF! | O19: =G19/$H$6 -> #REF!
A20: MC | B20: 4239.69 | C20: 791.28 | D20: =VLOOKUP(A20,'2025数据'!B:D,5,0)+VLOOKUP(A20,'2025数据'!B:E,6,0)+VLOOKUP(A20,'2025数据'!B:O,7,0) -> #REF! | E20: =D20-C20 -> #REF! | F20: 1176.28 | G20: =VLOOKUP(A20,'2025数据'!B:O,18,0)+VLOOKUP(A20,'2025数据'!B:G,8,0)+VLOOKUP(A20,'2025数据'!B:O,17,0) -> #REF! | H20: =G20-F20 -> #REF! | I20: 1561.28 | J20: 710.85 | M20: =B20/$B$6 -> 0.049155926 | N20: =D20/$E$6 -> #REF! | O20: =G20/$H$6 -> #REF!
A21: LT | B21: 2408 | C21: 0 | D21: =VLOOKUP(A21,'2025数据'!B:D,5,0)+VLOOKUP(A21,'2025数据'!B:E,6,0)+VLOOKUP(A21,'2025数据'!B:O,7,0) -> #N/A | E21: =D21-C21 -> #N/A | F21: 1204 | G21: =VLOOKUP(A21,'2025数据'!B:O,18,0)+VLOOKUP(A21,'2025数据'!B:G,8,0)+VLOOKUP(A21,'2025数据'!B:O,17,0) -> #N/A | H21: =G21-F21 -> #N/A | I21: 1204 | J21: 0 | M21: =B21/$B$6 -> 0.027918897 | N21: =D21/$E$6 -> #N/A | O21: =G21/$H$6 -> #N/A
A22: YTF | B22: 1540 | C22: 385 | D22: =VLOOKUP(A22,'2025数据'!B:D,5,0)+VLOOKUP(A22,'2025数据'!B:E,6,0)+VLOOKUP(A22,'2025数据'!B:O,7,0) -> #REF! | E22: =D22-C22 -> #REF! | F22: 770 | G22: =VLOOKUP(A22,'2025数据'!B:O,18,0)+VLOOKUP(A22,'2025数据'!B:G,8,0)+VLOOKUP(A22,'2025数据'!B:O,17,0) -> #REF! | H22: =G22-F22 -> #REF! | I22: 385 | J22: 0 | M22: =B22/$B$6 -> 0.017855109 | N22: =D22/$E$6 -> #REF! | O22: =G22/$H$6 -> #REF!
A23: LAVA | B23: 34974.1 | C23: 4483.5 | D23: =VLOOKUP(A23,'2025数据'!B:D,5,0)+VLOOKUP(A23,'2025数据'!B:E,6,0)+VLOOKUP(A23,'2025数据'!B:O,7,0) -> #REF! | E23: =D23-C23 -> #REF! | F23: 5087.6 | G23: =VLOOKUP(A23,'2025数据'!B:O,18,0)+VLOOKUP(A23,'2025数据'!B:G,8,0)+VLOOKUP(A23,'2025数据'!B:O,17,0) -> #REF! | H23: =G23-F23 -> #REF! | I23: 8687 | J23: 16716 | M23: =B23/$B$6 -> 0.40549763 | N23: =D23/$E$6 -> #REF! | O23: =G23/$H$6 -> #REF!
A24: SM | B24: 4631.2 | C24: 1311.1 | D24: =VLOOKUP(A24,'2025数据'!B:D,5,0)+VLOOKUP(A24,'2025数据'!B:E,6,0)+VLOOKUP(A24,'2025数据'!B:O,7,0) -> #REF! | E24: =D24-C24 -> #REF! | F24: 966 | G24: =VLOOKUP(A24,'2025数据'!B:O,18,0)+VLOOKUP(A24,'2025数据'!B:G,8,0)+VLOOKUP(A24,'2025数据'!B:O,17,0) -> #REF! | H24: =G24-F24 -> #REF! | I24: 1493.1 | J24: 861 | M24: =B24/$B$6 -> 0.053695181 | N24: =D24/$E$6 -> #REF! | O24: =G24/$H$6 -> #REF!
A25: MBC | B25: 3185.875 | C25: 1218.875 | D25: =VLOOKUP(A25,'2025数据'!B:D,5,0)+VLOOKUP(A25,'2025数据'!B:E,6,0)+VLOOKUP(A25,'2025数据'!B:O,7,0) -> #REF! | E25: =D25-C25 -> #REF! | F25: 861 | G25: =VLOOKUP(A25,'2025数据'!B:O,18,0)+VLOOKUP(A25,'2025数据'!B:G,8,0)+VLOOKUP(A25,'2025数据'!B:O,17,0) -> #REF! | H25: =G25-F25 -> #REF! | I25: 1106 | J25: 0 | M25: =B25/$B$6 -> 0.036937756 | N25: =D25/$E$6 -> #REF! | O25: =G25/$H$6 -> #REF!
A26: GDL | B26: 2128 | C26: 322 | D26: =VLOOKUP(A26,'2025数据'!B:D,5,0)+VLOOKUP(A26,'2025数据'!B:E,6,0)+VLOOKUP(A26,'2025数据'!B:O,7,0) -> #REF! | E26: =D26-C26 -> #REF! | F26: 322 | G26: =VLOOKUP(A26,'2025数据'!B:O,18,0)+VLOOKUP(A26,'2025数据'!B:G,8,0)+VLOOKUP(A26,'2025数据'!B:O,17,0) -> #REF! | H26: =G26-F26 -> #REF! | I26: 924 | J26: 560 | M26: =B26/$B$6 -> 0.024672514 | N26: =D26/$E$6 -> #REF! | O26: =G26/$H$6 -> #REF!
A27: Doro | B27: 84.28 | C27: 84.28 | D27: =VLOOKUP(A27,'2025数据'!B:D,5,0)+VLOOKUP(A27,'2025数据'!B:E,6,0)+VLOOKUP(A27,'2025数据'!B:O,7,0) -> #REF! | E27: =D27-C27 -> #REF! | F27: 0 | G27: =VLOOKUP(A27,'2025数据'!B:O,18,0)+VLOOKUP(A27,'2025数据'!B:G,8,0)+VLOOKUP(A27,'2025数据'!B:O,17,0) -> #REF! | H27: =G27-F27 -> #REF! | I27: 0 | J27: 0 | M27: =B27/$B$6 -> 0.0009771614 | N27: =D27/$E$6 -> #REF! | O27: =G27/$H$6 -> #REF!
A28: Wiko | B28: 9658.628 | C28: 305.312 | D28: =VLOOKUP(A28,'2025数据'!B:D,5,0)+VLOOKUP(A28,'2025数据'!B:E,6,0)+VLOOKUP(A28,'2025数据'!B:O,7,0) -> #REF! | E28: =D28-C28 -> #REF! | F28: 1844.836 | G28: =VLOOKUP(A28,'2025数据'!B:O,18,0)+VLOOKUP(A28,'2025数据'!B:G,8,0)+VLOOKUP(A28,'2025数据'!B:O,17,0) -> #REF! | H28: =G28-F28 -> #REF! | I28: 3561.74 | J28: 3946.74 | M28: =B28/$B$6 -> 0.11198432 | N28: =D28/$E$6 -> #REF! | O28: =G28/$H$6 -> #REF!
A29: TP | B29: 7096.8 | C29: 860 | D29: =VLOOKUP(A29,'2025数据'!B:D,5,0)+VLOOKUP(A29,'2025数据'!B:E,6,0)+VLOOKUP(A29,'2025数据'!B:O,7,0) -> #REF! | E29: =D29-C29 -> #REF! | F29: 1897 | G29: =VLOOKUP(A29,'2025数据'!B:O,18,0)+VLOOKUP(A29,'2025数据'!B:G,8,0)+VLOOKUP(A29,'2025数据'!B:O,17,0) -> #REF! | H29: =G29-F29 -> #REF! | I29: 2611 | J29: 1728.8 | M29: =B29/$B$6 -> 0.082281906 | N29: =D29/$E$6 -> #REF! | O29: =G29/$H$6 -> #REF!
... A31: AI | B31: 0 | C31: 0 | D31: =VLOOKUP(A31,'2025数据'!B:D,5,0)+VLOOKUP(A31,'2025数据'!B:E,6,0)+VLOOKUP(A31,'2025数据'!B:O,7,0) -> #REF! | E31: =D31-C31 -> #REF! | F31: 0 | G31: =VLOOKUP(A31,'2025数据'!B:O,18,0)+VLOOKUP(A31,'2025数据'!B:G,8,0)+VLOOKUP(A31,'2025数据'!B:O,17,0) -> #REF! | H31: =G31-F31 -> #REF! | I31: 0 | J31: 0 | M31: =B31/$B$6 -> 0 | N31: =D31/$E$6 -> #REF! | O31: =G31/$H$6 -> #REF!
A32: ZYB | B32: 40867.279 | C32: 11876.219 | D32: =VLOOKUP(A32,'2025数据'!B:D,5,0)+VLOOKUP(A32,'2025数据'!B:E,6,0)+VLOOKUP(A32,'2025数据'!B:O,7,0) -> #REF! | E32: =D32-C32 -> #REF! | F32: 9860.177 | G32: =VLOOKUP(A32,'2025数据'!B:O,18,0)+VLOOKUP(A32,'2025数据'!B:G,8,0)+VLOOKUP(A32,'2025数据'!B:O,17,0) -> #REF! | H32: =G32-F32 -> #REF! | I32: 9548.6726 | J32: 9582.2102
A33: Xiaodu | B33: 13281.934 | C33: 2809.3468 | D33: =VLOOKUP(A33,'2025数据'!B:D,5,0)+VLOOKUP(A33,'2025数据'!B:E,6,0)+VLOOKUP(A33,'2025数据'!B:O,7,0) -> #REF! | E33: =D33-C33 -> #REF! | F33: 3717.116 | G33: =VLOOKUP(A33,'2025数据'!B:O,18,0)+VLOOKUP(A33,'2025数据'!B:G,8,0)+VLOOKUP(A33,'2025数据'!B:O,17,0) -> #REF! | H33: =G33-F33 -> #REF! | I33: 3717.116 | J33: 3038.3549
A34: TAL | B34: 2550.832 | C34: 2192.187 | D34: =VLOOKUP(A34,'2025数据'!B:D,5,0)+VLOOKUP(A34,'2025数据'!B:E,6,0)+VLOOKUP(A34,'2025数据'!B:O,7,0) -> #REF! | E34: =D34-C34 -> #REF! | F34: 358.645 | G34: =VLOOKUP(A34,'2025数据'!B:O,18,0)+VLOOKUP(A34,'2025数据'!B:G,8,0)+VLOOKUP(A34,'2025数据'!B:O,17,0) -> #REF! | H34: =G34-F34 -> #REF! | I34: 0 | J34: 0
A35: KK | B35: 5000.0496 | C35: 0 | D35: 0 | E35: =D35-C35 -> 0 | F35: 1049.6071 | G35: =VLOOKUP(A35,'2025数据'!B:O,18,0)+VLOOKUP(A35,'2025数据'!B:G,8,0)+VLOOKUP(A35,'2025数据'!B:O,17,0) -> #REF! | H35: =G35-F35 -> #REF! | I35: 1911.5044 | J35: 2038.9381
A36: MT | B36: 11317.162 | C36: 7057.4892 | D36: =VLOOKUP(A36,'2025数据'!B:D,5,0)+VLOOKUP(A36,'2025数据'!B:E,6,0)+VLOOKUP(A36,'2025数据'!B:O,7,0) -> #REF! | E36: =D36-C36 -> #REF! | F36: 3187.1726 | G36: =VLOOKUP(A36,'2025数据'!B:O,18,0)+VLOOKUP(A36,'2025数据'!B:G,8,0)+VLOOKUP(A36,'2025数据'!B:O,17,0) -> #REF! | H36: =G36-F36 -> #REF! | I36: 1072.5 | J36: 0
A37: Didi | B37: 4132.653 | C37: 2266.1685 | D37: =VLOOKUP(A37,'2025数据'!B:D,5,0)+VLOOKUP(A37,'2025数据'!B:E,6,0)+VLOOKUP(A37,'2025数据'!B:O,7,0) -> #REF! | E37: =D37-C37 -> #REF! | F37: 1447.3909 | G37: =VLOOKUP(A37,'2025数据'!B:O,18,0)+VLOOKUP(A37,'2025数据'!B:G,8,0)+VLOOKUP(A37,'2025数据'!B:O,17,0) -> #REF! | H37: =G37-F37 -> #REF! | I37: 230.97345 | J37: 188.12018
A38: 哈啰 | B38: 1046.4938 | C38: 1046.4938 | D38: =VLOOKUP(A38,'2025数据'!B:D,5,0)+VLOOKUP(A38,'2025数据'!B:E,6,0)+VLOOKUP(A38,'2025数据'!B:O,7,0) -> #REF! | E38: =D38-C38 -> #REF! | F38: 0 | G38: =VLOOKUP(A38,'2025数据'!B:O,18,0)+VLOOKUP(A38,'2025数据'!B:G,8,0)+VLOOKUP(A38,'2025数据'!B:O,17,0) -> #REF! | H38: =G38-F38 -> #REF! | I38: 0 | J38: 0
A39: MY | B39: 0 | C39: 0 | D39: =VLOOKUP(A39,'2025数据'!B:D,5,0)+VLOOKUP(A39,'2025数据'!B:E,6,0)+VLOOKUP(A39,'2025数据'!B:O,7,0) -> #REF! | E39: =D39-C39 -> #REF! | F39: 0 | G39: =VLOOKUP(A39,'2025数据'!B:O,18,0)+VLOOKUP(A39,'2025数据'!B:G,8,0)+VLOOKUP(A39,'2025数据'!B:O,17,0) -> #REF! | H39: =G39-F39 -> #REF! | I39: 0 | J39: 0
A40: 新客户-Sherman | B40: 3992.45 | C40: 0 | D40: 0 | E40: =D40-C40 -> 0 | F40: 0 | G40: 0 | H40: =G40-F40 -> 0 | I40: 1732.5 | J40: 2259.95
A41: 日本MNVO | B41: 1050 | C41: 0 | D41: 0 | E41: =D41-C41 -> 0 | F41: 0 | G41: 0 | H41: =G41-F41 -> 0 | I41: 0 | J41: 1050
A42: TX | B42: 8664.742 | C42: 11.32646 | D42: =VLOOKUP(A42,'2025数据'!B:D,5,0)+VLOOKUP(A42,'2025数据'!B:E,6,0)+VLOOKUP(A42,'2025数据'!B:O,7,0) -> #REF! | E42: =D42-C42 -> #REF! | F42: 2265.292 | G42: =VLOOKUP(A42,'2025数据'!B:O,18,0)+VLOOKUP(A42,'2025数据'!B:G,8,0)+VLOOKUP(A42,'2025数据'!B:O,17,0) -> #REF! | H42: =G42-F42 -> #REF! | I42: 3397.9381 | J42: 2990.1855
A43: 巨鼎 | B43: 160.09487 | C43: 160.09487 | D43: =VLOOKUP(A43,'2025数据'!B:D,5,0)+VLOOKUP(A43,'2025数据'!B:E,6,0)+VLOOKUP(A43,'2025数据'!B:O,7,0) -> #REF! | E43: =D43-C43 -> #REF! | F43: 0 | G43: =VLOOKUP(A43,'2025数据'!B:O,18,0)+VLOOKUP(A43,'2025数据'!B:G,8,0)+VLOOKUP(A43,'2025数据'!B:O,17,0) -> #REF! | H43: =G43-F43 -> #REF! | I43: 0 | J43: 0
...

Sheet 与年度目标对比 (2)
A2: 客户 | B2: 全年保底 | C2: 占比 | D2: Q1 | E2: Q1 | F2: 偏差 | G2: Q2 | H2: Q2 | I2: 偏差 | J2: Q3 | K2: Q4
B3: 目标分解 | D3: 目标分解 | E3: 实际+计划 | G3: 目标分解 | H3: 计划 | J3: 目标分解 | K3: 目标分解
A4: ZTE | B4: =B16 -> 123850.18 | C4: =B4/B15 -> 0.33681491 | D4: =C16 -> 18672.113 | E4: =D16 -> #REF! | F4: =E4-D4 -> #REF! | G4: =F16 -> 25162.182 | H4: =G16 -> #REF! | I4: =H4-G4 -> #REF! | J4: =I16 -> 42457.158 | K4: =J16 -> 37558.725
A5: HMD | B5: =B17 -> 65416.12 | C5: =B5/367709.90128077 -> 0.17790144 | D5: =C17 -> 15695.4 | E5: =D17 -> #REF! | F5: =E5-D5 -> #REF! | G5: =F17 -> 15177.4 | H5: =G17 -> #REF! | I5: =H5-G5 -> #REF! | J5: =I17 -> 19693.8 | K5: =J17 -> 14849.52
A6: local king 客户 | B6: =B23+B28+B29+B18+B19+B30+B24+B20+B25+B21+B26+B22+B27 -> 86249.825 | C6: =B6/367709.90128077 -> 0.23455943 | D6: =C23+C28+C29+C18+C19+C30+C24+C20+C25+C21+C26+C22+C27 -> 14273.819 | E6: =D23+D28+D29+D18+D19+D30+D24+D20+D25+D21+D26+D22+D27 -> #REF! | F6: =E6-D6 -> #REF! | G6: =F23+F28+F29+F18+F19+F30+F24+F20+F25+F21+F26+F22+F27 -> 19268.356 | H6: =G23+G28+G29+G18+G19+G30+G24+G20+G25+G21+G26+G22+G27 -> #REF! | I6: =H6-G6 -> #REF! | J6: =I23+I28+I29+I18+I19+I30+I24+I20+I25+I21+I26+I22+I27 -> 25834.26 | K6: =J23+J28+J29+J18+J19+J30+J24+J20+J25+J21+J26+J22+J27 -> 26873.39
A7: 平板 | B7: =B31+B32+B34+B33 -> 61700.094 | C7: =B7/367709.90128077 -> 0.16779558 | D7: =C31+C32+C34+C33 -> 16877.753 | E7: =D31+D32+D34+D33 -> #REF! | F7: =E7-D7 -> #REF! | G7: =F31+F32+F34+F33 -> 14985.545 | H7: =G31+G32+G34+G33 -> #REF! | I7: =H7-G7 -> #REF! | J7: =I31+I32+I34+I33 -> 15177.293 | K7: =J31+J32+J34+J33 -> 14659.503
A8: 共享 | B8: =B35+B36+B37 -> 16496.309 | C8: =B8/367709.90128077 -> 0.044862291 | D8: =C35+C36+C37 -> 10370.151 | E8: =D35+D36+D37+D38 -> #REF! | F8: =E8-D8 -> #REF! | G8: =F35+F36+F37 -> 4634.5635 | H8: =G35+G36+G37+G38 -> #REF! | I8: =H8-G8 -> #REF! | J8: =I35+I36+I37 -> 1303.4735 | K8: =J35+J36+J37 -> 188.12018
A9: others | B9: =B41+B39+B40+B42+B43+B44+B45 -> 13997.375 | C9: =B9/367709.90128077 -> 0.038066354 | D9: =C41+C39+C40+C42+C43+C44+C45 -> 301.50982 | E9: =D41+D39+D40+D42+D43+D44+D45 -> #REF! | F9: =E9-D9 -> #REF! | G9: =F41+F39+F40+F42+F43+F44+F45 -> 2265.292 | H9: =G41+G39+G40+G42+G43+G44+G45 -> #REF! | I9: =H9-G9 -> #REF! | J9: =I41+I39+I40+I42+I43+I44+I45 -> 5130.4381 | K9: =J41+J39+J40+J42+J43+J44+J45 -> 6300.1355
A10: 合计 | B10: =SUM(B4:B9) -> 367709.9 | D10: =SUM(D4:D9) -> 76190.746 | E10: =SUM(E4:E9) -> #REF! | F10: =SUM(F4:F9) -> #REF! | G10: =SUM(G4:G9) -> 81493.338 | H10: =SUM(H4:H9) -> #REF! | I10: =SUM(I4:I9) -> #REF! | J10: =SUM(J4:J9) -> 109596.42 | K10: =SUM(K4:K9) -> 100429.39
D11: =D10/B10 -> 0.20720341 | E11: =E10/B10 -> #REF! | G11: =G10/B10 -> 0.221624 | H11: =H10/B10 -> #REF! | J11: =J10/B10 -> 0.29805132 | K11: =K10/B10 -> 0.27312127
A13: 客户 | B13: 全年保底 | C13: Q1 | D13: Q1 | E13: 偏差 | F13: Q2 | G13: Q2 | H13: 偏差 | I13: Q3 | J13: Q4
B14: 目标分解 | C14: 目标分解 | D14: 实际 | F14: 目标分解 | G14: 计划 | I14: 目标分解 | J14: 目标分解
A15: 汇总 | B15: =SUM(B16:B45) -> 367709.9 | C15: =SUM(C16:C45) -> 76190.746 | D15: =SUM(D16:D45) -> #REF! | E15: =SUM(E16:E45) -> #REF! | F15: =SUM(F16:F45) -> 81493.338 | G15: =SUM(G16:G45) -> #REF! | H15: =SUM(H16:H45) -> #REF! | I15: =SUM(I16:I45) -> 109596.42 | J15: =SUM(J16:J45) -> 100429.39
A16: ZTE | B16: 123850.18 | C16: 18672.113 | D16: =VLOOKUP(A16,'2025数据'!B:D,5,0)+VLOOKUP(A16,'2025数据'!B:E,6,0)+VLOOKUP(A16,'2025数据'!B:O,17,0) -> #REF! | E16: =D16-C16 -> #REF! | F16: 25162.182 | G16: =VLOOKUP(A16,'2025数据'!B:O,18,0)+VLOOKUP(A16,'2025数据'!B:O,19,0)+VLOOKUP(A16,'2025数据'!B:O,17,0) -> #REF! | H16: =G16-F16 -> #REF! | I16: 42457.158 | J16: 37558.725
A17: HMD | B17: 65416.12 | C17: 15695.4 | D17: =VLOOKUP(A17,'2025数据'!B:D,5,0)+VLOOKUP(A17,'2025数据'!B:E,6,0)+VLOOKUP(A17,'2025数据'!B:O,17,0) -> #REF! | E17: =D17-C17 -> #REF! | F17: 15177.4 | G17: =VLOOKUP(A17,'2025数据'!B:O,18,0)+VLOOKUP(A17,'2025数据'!B:O,19,0)+VLOOKUP(A17,'2025数据'!B:O,17,0) -> #REF! | H17: =G17-F17 -> #REF! | I17: 19693.8 | J17: 14849.52
A18: BLU | B18: 5762.68 | C18: 2048.9 | D18: =VLOOKUP(A18,'2025数据'!B:D,5,0)+VLOOKUP(A18,'2025数据'!B:E,6,0)+VLOOKUP(A18,'2025数据'!B:O,17,0) -> #REF! | E18: =D18-C18 -> #REF! | F18: 1624.14 | G18: =VLOOKUP(A18,'2025数据'!B:O,18,0)+VLOOKUP(A18,'2025数据'!B:O,19,0)+VLOOKUP(A18,'2025数据'!B:O,17,0) -> #REF! | H18: =G18-F18 -> #REF! | I18: 1417.64 | J18: 672 | L18: =B18/$B$6 -> 0.066813817
A19: LF | B19: 5635 | C19: 1820 | D19: =VLOOKUP(A19,'2025数据'!B:D,5,0)+VLOOKUP(A19,'2025数据'!B:E,6,0)+VLOOKUP(A19,'2025数据'!B:O,17,0) -> #REF! | E19: =D19-C19 -> #REF! | F19: 2450 | G19: =VLOOKUP(A19,'2025数据'!B:O,18,0)+VLOOKUP(A19,'2025数据'!B:O,19,0)+VLOOKUP(A19,'2025数据'!B:O,17,0) -> #REF! | H19: =G19-F19 -> #REF! | I19: 1050 | J19: 315 | L19: =B19/$B$6 -> 0.065333466
A20: MC | B20: 4239.69 | C20: 791.28 | D20: =VLOOKUP(A20,'2025数据'!B:D,5,0)+VLOOKUP(A20,'2025数据'!B:E,6,0)+VLOOKUP(A20,'2025数据'!B:O,17,0) -> #REF! | E20: =D20-C20 -> #REF! | F20: 1176.28 | G20: =VLOOKUP(A20,'2025数据'!B:O,18,0)+VLOOKUP(A20,'2025数据'!B:O,19,0)+VLOOKUP(A20,'2025数据'!B:O,17,0) -> #REF! | H20: =G20-F20 -> #REF! | I20: 1561.28 | J20: 710.85 | L20: =B20/$B$6 -> 0.049155926
A21: LT | B21: 2408 | C21: 0 | D21: =VLOOKUP(A21,'2025数据'!B:D,5,0)+VLOOKUP(A21,'2025数据'!B:E,6,0)+VLOOKUP(A21,'2025数据'!B:O,17,0) -> #N/A | E21: =D21-C21 -> #N/A | F21: 1204 | G21: =VLOOKUP(A21,'2025数据'!B:O,18,0)+VLOOKUP(A21,'2025数据'!B:O,19,0)+VLOOKUP(A21,'2025数据'!B:O,17,0) -> #N/A | H21: =G21-F21 -> #N/A | I21: 1204 | J21: 0 | L21: =B21/$B$6 -> 0.027918897
A22: YTF | B22: 1540 | C22: 385 | D22: =VLOOKUP(A22,'2025数据'!B:D,5,0)+VLOOKUP(A22,'2025数据'!B:E,6,0)+VLOOKUP(A22,'2025数据'!B:O,17,0) -> #REF! | E22: =D22-C22 -> #REF! | F22: 770 | G22: =VLOOKUP(A22,'2025数据'!B:O,18,0)+VLOOKUP(A22,'2025数据'!B:O,19,0)+VLOOKUP(A22,'2025数据'!B:O,17,0) -> #REF! | H22: =G22-F22 -> #REF! | I22: 385 | J22: 0 | L22: =B22/$B$6 -> 0.017855109
A23: LAVA | B23: 34974.1 | C23: 4483.5 | D23: =VLOOKUP(A23,'2025数据'!B:D,5,0)+VLOOKUP(A23,'2025数据'!B:E,6,0)+VLOOKUP(A23,'2025数据'!B:O,17,0) -> #REF! | E23: =D23-C23 -> #REF! | F23: 5087.6 | G23: =VLOOKUP(A23,'2025数据'!B:O,18,0)+VLOOKUP(A23,'2025数据'!B:O,19,0)+VLOOKUP(A23,'2025数据'!B:O,17,0) -> #REF! | H23: =G23-F23 -> #REF! | I23: 8687 | J23: 16716 | L23: =B23/$B$6 -> 0.40549763
A24: SM | B24: 4631.2 | C24: 1311.1 | D24: =VLOOKUP(A24,'2025数据'!B:D,5,0)+VLOOKUP(A24,'2025数据'!B:E,6,0)+VLOOKUP(A24,'2025数据'!B:O,17,0) -> #REF! | E24: =D24-C24 -> #REF! | F24: 966 | G24: =VLOOKUP(A24,'2025数据'!B:O,18,0)+VLOOKUP(A24,'2025数据'!B:O,19,0)+VLOOKUP(A24,'2025数据'!B:O,17,0) -> #REF! | H24: =G24-F24 -> #REF! | I24: 1493.1 | J24: 861 | L24: =B24/$B$6 -> 0.053695181
A25: MBC | B25: 3185.875 | C25: 1218.875 | D25: =VLOOKUP(A25,'2025数据'!B:D,5,0)+VLOOKUP(A25,'2025数据'!B:E,6,0)+VLOOKUP(A25,'2025数据'!B:O,17,0) -> #REF! | E25: =D25-C25 -> #REF! | F25: 861 | G25: =VLOOKUP(A25,'2025数据'!B:O,18,0)+VLOOKUP(A25,'2025数据'!B:O,19,0)+VLOOKUP(A25,'2025数据'!B:O,17,0) -> #REF! | H25: =G25-F25 -> #REF! | I25: 1106 | J25: 0 | L25: =B25/$B$6 -> 0.036937756
A26: GDL | B26: 2128 | C26: 322 | D26: =VLOOKUP(A26,'2025数据'!B:D,5,0)+VLOOKUP(A26,'2025数据'!B:E,6,0)+VLOOKUP(A26,'2025数据'!B:O,17,0) -> #REF! | E26: =D26-C26 -> #REF! | F26: 322 | G26: =VLOOKUP(A26,'2025数据'!B:O,18,0)+VLOOKUP(A26,'2025数据'!B:O,19,0)+VLOOKUP(A26,'2025数据'!B:O,17,0) -> #REF! | H26: =G26-F26 -> #REF! | I26: 924 | J26: 560 | L26: =B26/$B$6 -> 0.024672514
A27: Doro | B27: 84.28 | C27: 84.28 | D27: =VLOOKUP(A27,'2025数据'!B:D,5,0)+VLOOKUP(A27,'2025数据'!B:E,6,0)+VLOOKUP(A27,'2025数据'!B:O,17,0) -> #REF! | E27: =D27-C27 -> #REF! | F27: 0 | G27: =VLOOKUP(A27,'2025数据'!B:O,18,0)+VLOOKUP(A27,'2025数据'!B:O,19,0)+VLOOKUP(A27,'2025数据'!B:O,17,0) -> #REF! | H27: =G27-F27 -> #REF! | I27: 0 | J27: 0 | L27: =B27/$B$6 -> 0.0009771614
A28: Wiko | B28: 9658.628 | C28: 305.312 | D28: =VLOOKUP(A28,'2025数据'!B:D,5,0)+VLOOKUP(A28,'2025数据'!B:E,6,0)+VLOOKUP(A28,'2025数据'!B:O,17,0) -> #REF! | E28: =D28-C28 -> #REF! | F28: 1844.836 | G28: =VLOOKUP(A28,'2025数据'!B:O,18,0)+VLOOKUP(A28,'2025数据'!B:O,19,0)+VLOOKUP(A28,'2025数据'!B:O,17,0) -> #REF! | H28: =G28-F28 -> #REF! | I28: 3561.74 | J28: 3946.74 | L28: =B28/$B$6 -> 0.11198432
A29: TP | B29: 7096.8 | C29: 860 | D29: =VLOOKUP(A29,'2025数据'!B:D,5,0)+VLOOKUP(A29,'2025数据'!B:E,6,0)+VLOOKUP(A29,'2025数据'!B:O,17,0) -> #REF! | E29: =D29-C29 -> #REF! | F29: 1897 | G29: =VLOOKUP(A29,'2025数据'!B:O,18,0)+VLOOKUP(A29,'2025数据'!B:O,19,0)+VLOOKUP(A29,'2025数据'!B:O,17,0) -> #REF! | H29: =G29-F29 -> #REF! | I29: 2611 | J29: 1728.8 | L29: =B29/$B$6 -> 0.082281906
A30: XM | B30: 4905.572 | C30: 643.572 | D30: =VLOOKUP(A30,'2025数据'!B:D,5,0)+VLOOKUP(A30,'2025数据'!B:E,6,0)+VLOOKUP(A30,'2025数据'!B:O,17,0) -> #REF! | E30: =D30-C30 -> #REF! | F30: 1065.5 | G30: =VLOOKUP(A30,'2025数据'!B:O,18,0)+VLOOKUP(A30,'2025数据'!B:O,19,0)+VLOOKUP(A30,'2025数据'!B:O,17,0) -> #REF! | H30: =G30-F30 -> #REF! | I30: 1833.5 | J30: 1363 | L30: =B30/$B$6 -> 0.056876313
A31: ZYB | B31: 40867.279 | C31: 11876.219 | D31: =VLOOKUP(A31,'2025数据'!B:D,5,0)+VLOOKUP(A31,'2025数据'!B:E,6,0)+VLOOKUP(A31,'2025数据'!B:O,17,0) -> #REF! | E31: =D31-C31 -> #REF! | F31: 9860.177 | G31: =VLOOKUP(A31,'2025数据'!B:O,18,0)+VLOOKUP(A31,'2025数据'!B:O,19,0)+VLOOKUP(A31,'2025数据'!B:O,17,0) -> #REF! | H31: =G31-F31 -> #REF! | I31: 9548.6726 | J31: 9582.2102
A32: Xiaodu | B32: 13281.934 | C32: 2809.3468 | D32: =VLOOKUP(A32,'2025数据'!B:D,5,0)+VLOOKUP(A32,'2025数据'!B:E,6,0)+VLOOKUP(A32,'2025数据'!B:O,17,0) -> #REF! | E32: =D32-C32 -> #REF! | F32: 3717.116 | G32: =VLOOKUP(A32,'2025数据'!B:O,18,0)+VLOOKUP(A32,'2025数据'!B:O,19,0)+VLOOKUP(A32,'2025数据'!B:O,17,0) -> #REF! | H32: =G32-F32 -> #REF! | I32: 3717.116 | J32: 3038.3549
A33: TAL | B33: 2550.832 | C33: 2192.187 | D33: =VLOOKUP(A33,'2025数据'!B:D,5,0)+VLOOKUP(A33,'2025数据'!B:E,6,0)+VLOOKUP(A33,'2025数据'!B:O,17,0) -> #REF! | E33: =D33-C33 -> #REF! | F33: 358.645 | G33: =VLOOKUP(A33,'2025数据'!B:O,18,0)+VLOOKUP(A33,'2025数据'!B:O,19,0)+VLOOKUP(A33,'2025数据'!B:O,17,0) -> #REF! | H33: =G33-F33 -> #REF! | I33: 0 | J33: 0
A34: KK | B34: 5000.0496 | C34: 0 | D34: 0 | E34: =D34-C34 -> 0 | F34: 1049.6071 | G34: =VLOOKUP(A34,'2025数据'!B:O,18,0)+VLOOKUP(A34,'2025数据'!B:O,19,0)+VLOOKUP(A34,'2025数据'!B:O,17,0) -> #REF! | H34: =G34-F34 -> #REF! | I34: 1911.5044 | J34: 2038.9381
A35: MT | B35: 11317.162 | C35: 7057.4892 | D35: =VLOOKUP(A35,'2025数据'!B:D,5,0)+VLOOKUP(A35,'2025数据'!B:E,6,0)+VLOOKUP(A35,'2025数据'!B:O,17,0) -> #REF! | E35: =D35-C35 -> #REF! | F35: 3187.1726 | G35: =VLOOKUP(A35,'2025数据'!B:O,18,0)+VLOOKUP(A35,'2025数据'!B:O,19,0)+VLOOKUP(A35,'2025数据'!B:O,17,0) -> #REF! | H35: =G35-F35 -> #REF! | I35: 1072.5 | J35: 0
A36: Didi | B36: 4132.653 | C36: 2266.1685 | D36: =VLOOKUP(A36,'2025数据'!B:D,5,0)+VLOOKUP(A36,'2025数据'!B:E,6,0)+VLOOKUP(A36,'2025数据'!B:O,17,0) -> #REF! | E36: =D36-C36 -> #REF! | F36: 1447.3909 | G36: =VLOOKUP(A36,'2025数据'!B:O,18,0)+VLOOKUP(A36,'2025数据'!B:O,19,0)+VLOOKUP(A36,'2025数据'!B:O,17,0) -> #REF! | H36: =G36-F36 -> #REF! | I36: 230.97345 | J36: 188.12018
A37: 哈啰 | B37: 1046.4938 | C37: 1046.4938 | D37: =VLOOKUP(A37,'2025数据'!B:D,5,0)+VLOOKUP(A37,'2025数据'!B:E,6,0)+VLOOKUP(A37,'2025数据'!B:O,17,0) -> #REF! | E37: =D37-C37 -> #REF! | F37: 0 | G37: =VLOOKUP(A37,'2025数据'!B:O,18,0)+VLOOKUP(A37,'2025数据'!B:O,19,0)+VLOOKUP(A37,'2025数据'!B:O,17,0) -> #REF! | H37: =G37-F37 -> #REF! | I37: 0 | J37: 0
A38: MY | B38: 0 | C38: 0 | D38: =VLOOKUP(A38,'2025数据'!B:D,5,0)+VLOOKUP(A38,'2025数据'!B:E,6,0)+VLOOKUP(A38,'2025数据'!B:O,17,0) -> #REF! | E38: =D38-C38 -> #REF! | F38: 0 | G38: =VLOOKUP(A38,'2025数据'!B:O,18,0)+VLOOKUP(A38,'2025数据'!B:O,19,0)+VLOOKUP(A38,'2025数据'!B:O,17,0) -> #REF! | H38: =G38-F38 -> #REF! | I38: 0 | J38: 0
A39: 新客户-Sherman | B39: 3992.45 | C39: 0 | D39: 0 | E39: =D39-C39 -> 0 | F39: 0 | G39: 0 | H39: =G39-F39 -> 0 | I39: 1732.5 | J39: 2259.95
A40: 日本MNVO | B40: 1050 | C40: 0 | D40: 0 | E40: =D40-C40 -> 0 | F40: 0 | G40: 0 | H40: =G40-F40 -> 0 | I40: 0 | J40: 1050
A41: TX | B41: 8664.742 | C41: 11.32646 | D41: =VLOOKUP(A41,'2025数据'!B:D,5,0)+VLOOKUP(A41,'2025数据'!B:E,6,0)+VLOOKUP(A41,'2025数据'!B:O,17,0) -> #REF! | E41: =D41-C41 -> #REF! | F41: 2265.292 | G41: =VLOOKUP(A41,'2025数据'!B:O,18,0)+VLOOKUP(A41,'2025数据'!B:O,19,0)+VLOOKUP(A41,'2025数据'!B:O,17,0) -> #REF! | H41: =G41-F41 -> #REF! | I41: 3397.9381 | J41: 2990.1855
A42: 巨鼎 | B42: 160.09487 | C42: 160.09487 | D42: =VLOOKUP(A42,'2025数据'!B:D,5,0)+VLOOKUP(A42,'2025数据'!B:E,6,0)+VLOOKUP(A42,'2025数据'!B:O,17,0) -> #REF! | E42: =D42-C42 -> #REF! | F42: 0 | G42: =VLOOKUP(A42,'2025数据'!B:O,18,0)+VLOOKUP(A42,'2025数据'!B:O,19,0)+VLOOKUP(A42,'2025数据'!B:O,17,0) -> #REF! | H42: =G42-F42 -> #REF! | I42: 0 | J42: 0
...
